Workbook

Sheet Statistics
B2: AUTOBONO — Statistics
B3: Counted automatically from the Sales date column on the 2024 tab, from January 2024 (Brutto profit, Sale price, Sale time, Cash stuck). Nothing to type here — new cars, months and years appear by themselves.
B5: Quick view
B6: Period | C6: Cars bought | D6: Cars sold | E6: Profit | F6: Avg profit / car | G6: Half profit (each of you) | H6: Sales total | I6: Avg days online | J6: Avg days bought → sold
B7: This month | C7: =IF(FALSE,"",COUNTIFS('2024'!$AD$5:$AD$178,">="&DATE(YEAR(TODAY()),MONTH(TODAY()),1),'2024'!$AD$5:$AD$178,"<"&DATE(YEAR(TODAY()),MONTH(TODAY())+1,1))) | D7: =IF(FALSE,"",COUNTIFS('2024'!$AG$5:$AG$178,">="&DATE(YEAR(TODAY()),MONTH(TODAY()),1),'2024'!$AG$5:$AG$178,"<"&DATE(YEAR(TODAY()),MONTH(TODAY())+1,1))) | E7: =IF(FALSE,"",SUMIFS('2024'!$X$5:$X$178,'2024'!$AG$5:$AG$178,">="&DATE(YEAR(TODAY()),MONTH(TODAY()),1),'2024'!$AG$5:$AG$178,"<"&DATE(YEAR(TODAY()),MONTH(TODAY())+1,1))) | F7: =IF(N(D7)=0,"",E7/D7) | G7: =IF(E7="","",E7/2) | H7: =IF(FALSE,"",SUMIFS('2024'!$V$5:$V$178,'2024'!$AG$5:$AG$178,">="&DATE(YEAR(TODAY()),MONTH(TODAY()),1),'2024'!$AG$5:$AG$178,"<"&DATE(YEAR(TODAY()),MONTH(TODAY())+1,1))) | I7: =IF(N(D7)=0,"",(SUMIFS('2024'!$AH$5:$AH$178,'2024'!$AG$5:$AG$178,">="&DATE(YEAR(TODAY()),MONTH(TODAY()),1),'2024'!$AG$5:$AG$178,"<"&DATE(YEAR(TODAY()),MONTH(TODAY())+1,1)))/D7) | J7: =IF(N(D7)=0,"",(SUMIFS('2024'!$AI$5:$AI$178,'2024'!$AG$5:$AG$178,">="&DATE(YEAR(TODAY()),MONTH(TODAY()),1),'2024'!$AG$5:$AG$178,"<"&DATE(YEAR(TODAY()),MONTH(TODAY())+1,1)))/D7)
B8: Last month | C8: =IF(FALSE,"",COUNTIFS('2024'!$AD$5:$AD$178,">="&DATE(YEAR(TODAY()),MONTH(TODAY())-1,1),'2024'!$AD$5:$AD$178,"<"&DATE(YEAR(TODAY()),MONTH(TODAY()),1))) | D8: =IF(FALSE,"",COUNTIFS('2024'!$AG$5:$AG$178,">="&DATE(YEAR(TODAY()),MONTH(TODAY())-1,1),'2024'!$AG$5:$AG$178,"<"&DATE(YEAR(TODAY()),MONTH(TODAY()),1))) | E8: =IF(FALSE,"",SUMIFS('2024'!$X$5:$X$178,'2024'!$AG$5:$AG$178,">="&DATE(YEAR(TODAY()),MONTH(TODAY())-1,1),'2024'!$AG$5:$AG$178,"<"&DATE(YEAR(TODAY()),MONTH(TODAY()),1))) | F8: =IF(N(D8)=0,"",E8/D8) | G8: =IF(E8="","",E8/2) | H8: =IF(FALSE,"",SUMIFS('2024'!$V$5:$V$178,'2024'!$AG$5:$AG$178,">="&DATE(YEAR(TODAY()),MONTH(TODAY())-1,1),'2024'!$AG$5:$AG$178,"<"&DATE(YEAR(TODAY()),MONTH(TODAY()),1))) | I8: =IF(N(D8)=0,"",(SUMIFS('2024'!$AH$5:$AH$178,'2024'!$AG$5:$AG$178,">="&DATE(YEAR(TODAY()),MONTH(TODAY())-1,1),'2024'!$AG$5:$AG$178,"<"&DATE(YEAR(TODAY()),MONTH(TODAY()),1)))/D8) | J8: =IF(N(D8)=0,"",(SUMIFS('2024'!$AI$5:$AI$178,'2024'!$AG$5:$AG$178,">="&DATE(YEAR(TODAY()),MONTH(TODAY())-1,1),'2024'!$AG$5:$AG$178,"<"&DATE(YEAR(TODAY()),MONTH(TODAY()),1)))/D8)
B9: This year | C9: =IF(FALSE,"",COUNTIFS('2024'!$AD$5:$AD$178,">="&DATE(YEAR(TODAY()),1,1),'2024'!$AD$5:$AD$178,"<"&DATE(YEAR(TODAY())+1,1,1))) | D9: =IF(FALSE,"",COUNTIFS('2024'!$AG$5:$AG$178,">="&DATE(YEAR(TODAY()),1,1),'2024'!$AG$5:$AG$178,"<"&DATE(YEAR(TODAY())+1,1,1))) | E9: =IF(FALSE,"",SUMIFS('2024'!$X$5:$X$178,'2024'!$AG$5:$AG$178,">="&DATE(YEAR(TODAY()),1,1),'2024'!$AG$5:$AG$178,"<"&DATE(YEAR(TODAY())+1,1,1))) | F9: =IF(N(D9)=0,"",E9/D9) | G9: =IF(E9="","",E9/2) | H9: =IF(FALSE,"",SUMIFS('2024'!$V$5:$V$178,'2024'!$AG$5:$AG$178,">="&DATE(YEAR(TODAY()),1,1),'2024'!$AG$5:$AG$178,"<"&DATE(YEAR(TODAY())+1,1,1))) | I9: =IF(N(D9)=0,"",(SUMIFS('2024'!$AH$5:$AH$178,'2024'!$AG$5:$AG$178,">="&DATE(YEAR(TODAY()),1,1),'2024'!$AG$5:$AG$178,"<"&DATE(YEAR(TODAY())+1,1,1)))/D9) | J9: =IF(N(D9)=0,"",(SUMIFS('2024'!$AI$5:$AI$178,'2024'!$AG$5:$AG$178,">="&DATE(YEAR(TODAY()),1,1),'2024'!$AG$5:$AG$178,"<"&DATE(YEAR(TODAY())+1,1,1)))/D9)
B10: Last year | C10: =IF(FALSE,"",COUNTIFS('2024'!$AD$5:$AD$178,">="&DATE(YEAR(TODAY())-1,1,1),'2024'!$AD$5:$AD$178,"<"&DATE(YEAR(TODAY()),1,1))) | D10: =IF(FALSE,"",COUNTIFS('2024'!$AG$5:$AG$178,">="&DATE(YEAR(TODAY())-1,1,1),'2024'!$AG$5:$AG$178,"<"&DATE(YEAR(TODAY()),1,1))) | E10: =IF(FALSE,"",SUMIFS('2024'!$X$5:$X$178,'2024'!$AG$5:$AG$178,">="&DATE(YEAR(TODAY())-1,1,1),'2024'!$AG$5:$AG$178,"<"&DATE(YEAR(TODAY()),1,1))) | F10: =IF(N(D10)=0,"",E10/D10) | G10: =IF(E10="","",E10/2) | H10: =IF(FALSE,"",SUMIFS('2024'!$V$5:$V$178,'2024'!$AG$5:$AG$178,">="&DATE(YEAR(TODAY())-1,1,1),'2024'!$AG$5:$AG$178,"<"&DATE(YEAR(TODAY()),1,1))) | I10: =IF(N(D10)=0,"",(SUMIFS('2024'!$AH$5:$AH$178,'2024'!$AG$5:$AG$178,">="&DATE(YEAR(TODAY())-1,1,1),'2024'!$AG$5:$AG$178,"<"&DATE(YEAR(TODAY()),1,1)))/D10) | J10: =IF(N(D10)=0,"",(SUMIFS('2024'!$AI$5:$AI$178,'2024'!$AG$5:$AG$178,">="&DATE(YEAR(TODAY())-1,1,1),'2024'!$AG$5:$AG$178,"<"&DATE(YEAR(TODAY()),1,1)))/D10)
B11: Last 12 months | C11: =IF(FALSE,"",COUNTIFS('2024'!$AD$5:$AD$178,">="&EDATE(DATE(YEAR(TODAY()),MONTH(TODAY()),1),-11),'2024'!$AD$5:$AD$178,"<"&DATE(YEAR(TODAY()),MONTH(TODAY())+1,1))) | D11: =IF(FALSE,"",COUNTIFS('2024'!$AG$5:$AG$178,">="&EDATE(DATE(YEAR(TODAY()),MONTH(TODAY()),1),-11),'2024'!$AG$5:$AG$178,"<"&DATE(YEAR(TODAY()),MONTH(TODAY())+1,1))) | E11: =IF(FALSE,"",SUMIFS('2024'!$X$5:$X$178,'2024'!$AG$5:$AG$178,">="&EDATE(DATE(YEAR(TODAY()),MONTH(TODAY()),1),-11),'2024'!$AG$5:$AG$178,"<"&DATE(YEAR(TODAY()),MONTH(TODAY())+1,1))) | F11: =IF(N(D11)=0,"",E11/D11) | G11: =IF(E11="","",E11/2) | H11: =IF(FALSE,"",SUMIFS('2024'!$V$5:$V$178,'2024'!$AG$5:$AG$178,">="&EDATE(DATE(YEAR(TODAY()),MONTH(TODAY()),1),-11),'2024'!$AG$5:$AG$178,"<"&DATE(YEAR(TODAY()),MONTH(TODAY())+1,1))) | I11: =IF(N(D11)=0,"",(SUMIFS('2024'!$AH$5:$AH$178,'2024'!$AG$5:$AG$178,">="&EDATE(DATE(YEAR(TODAY()),MONTH(TODAY()),1),-11),'2024'!$AG$5:$AG$178,"<"&DATE(YEAR(TODAY()),MONTH(TODAY())+1,1)))/D11) | J11: =IF(N(D11)=0,"",(SUMIFS('2024'!$AI$5:$AI$178,'2024'!$AG$5:$AG$178,">="&EDATE(DATE(YEAR(TODAY()),MONTH(TODAY()),1),-11),'2024'!$AG$5:$AG$178,"<"&DATE(YEAR(TODAY()),MONTH(TODAY())+1,1)))/D11)
B13: By year — a new year appears by itself on 1 January
B14: Year | C14: Cars bought | D14: Cars sold | E14: Profit | F14: Avg profit / car | G14: Half profit (each of you) | H14: Sales total | I14: Avg days online | J14: Avg days bought → sold
B15: =IF(2024>YEAR(TODAY()),"",2024) | C15: =IF(2024>YEAR(TODAY()),"",COUNTIFS('2024'!$AD$5:$AD$178,">="&DATE(2024,1,1),'2024'!$AD$5:$AD$178,"<"&DATE(2025,1,1))) | D15: =IF(2024>YEAR(TODAY()),"",COUNTIFS('2024'!$AG$5:$AG$178,">="&DATE(2024,1,1),'2024'!$AG$5:$AG$178,"<"&DATE(2025,1,1))) | E15: =IF(2024>YEAR(TODAY()),"",SUMIFS('2024'!$X$5:$X$178,'2024'!$AG$5:$AG$178,">="&DATE(2024,1,1),'2024'!$AG$5:$AG$178,"<"&DATE(2025,1,1))) | F15: =IF(N(D15)=0,"",E15/D15) | G15: =IF(E15="","",E15/2) | H15: =IF(2024>YEAR(TODAY()),"",SUMIFS('2024'!$V$5:$V$178,'2024'!$AG$5:$AG$178,">="&DATE(2024,1,1),'2024'!$AG$5:$AG$178,"<"&DATE(2025,1,1))) | I15: =IF(N(D15)=0,"",(SUMIFS('2024'!$AH$5:$AH$178,'2024'!$AG$5:$AG$178,">="&DATE(2024,1,1),'2024'!$AG$5:$AG$178,"<"&DATE(2025,1,1)))/D15) | J15: =IF(N(D15)=0,"",(SUMIFS('2024'!$AI$5:$AI$178,'2024'!$AG$5:$AG$178,">="&DATE(2024,1,1),'2024'!$AG$5:$AG$178,"<"&DATE(2025,1,1)))/D15)
B16: =IF(2025>YEAR(TODAY()),"",2025) | C16: =IF(2025>YEAR(TODAY()),"",COUNTIFS('2024'!$AD$5:$AD$178,">="&DATE(2025,1,1),'2024'!$AD$5:$AD$178,"<"&DATE(2026,1,1))) | D16: =IF(2025>YEAR(TODAY()),"",COUNTIFS('2024'!$AG$5:$AG$178,">="&DATE(2025,1,1),'2024'!$AG$5:$AG$178,"<"&DATE(2026,1,1))) | E16: =IF(2025>YEAR(TODAY()),"",SUMIFS('2024'!$X$5:$X$178,'2024'!$AG$5:$AG$178,">="&DATE(2025,1,1),'2024'!$AG$5:$AG$178,"<"&DATE(2026,1,1))) | F16: =IF(N(D16)=0,"",E16/D16) | G16: =IF(E16="","",E16/2) | H16: =IF(2025>YEAR(TODAY()),"",SUMIFS('2024'!$V$5:$V$178,'2024'!$AG$5:$AG$178,">="&DATE(2025,1,1),'2024'!$AG$5:$AG$178,"<"&DATE(2026,1,1))) | I16: =IF(N(D16)=0,"",(SUMIFS('2024'!$AH$5:$AH$178,'2024'!$AG$5:$AG$178,">="&DATE(2025,1,1),'2024'!$AG$5:$AG$178,"<"&DATE(2026,1,1)))/D16) | J16: =IF(N(D16)=0,"",(SUMIFS('2024'!$AI$5:$AI$178,'2024'!$AG$5:$AG$178,">="&DATE(2025,1,1),'2024'!$AG$5:$AG$178,"<"&DATE(2026,1,1)))/D16)
B17: =IF(2026>YEAR(TODAY()),"",2026) | C17: =IF(2026>YEAR(TODAY()),"",COUNTIFS('2024'!$AD$5:$AD$178,">="&DATE(2026,1,1),'2024'!$AD$5:$AD$178,"<"&DATE(2027,1,1))) | D17: =IF(2026>YEAR(TODAY()),"",COUNTIFS('2024'!$AG$5:$AG$178,">="&DATE(2026,1,1),'2024'!$AG$5:$AG$178,"<"&DATE(2027,1,1))) | E17: =IF(2026>YEAR(TODAY()),"",SUMIFS('2024'!$X$5:$X$178,'2024'!$AG$5:$AG$178,">="&DATE(2026,1,1),'2024'!$AG$5:$AG$178,"<"&DATE(2027,1,1))) | F17: =IF(N(D17)=0,"",E17/D17) | G17: =IF(E17="","",E17/2) | H17: =IF(2026>YEAR(TODAY()),"",SUMIFS('2024'!$V$5:$V$178,'2024'!$AG$5:$AG$178,">="&DATE(2026,1,1),'2024'!$AG$5:$AG$178,"<"&DATE(2027,1,1))) | I17: =IF(N(D17)=0,"",(SUMIFS('2024'!$AH$5:$AH$178,'2024'!$AG$5:$AG$178,">="&DATE(2026,1,1),'2024'!$AG$5:$AG$178,"<"&DATE(2027,1,1)))/D17) | J17: =IF(N(D17)=0,"",(SUMIFS('2024'!$AI$5:$AI$178,'2024'!$AG$5:$AG$178,">="&DATE(2026,1,1),'2024'!$AG$5:$AG$178,"<"&DATE(2027,1,1)))/D17)
B18: =IF(2027>YEAR(TODAY()),"",2027) | C18: =IF(2027>YEAR(TODAY()),"",COUNTIFS('2024'!$AD$5:$AD$178,">="&DATE(2027,1,1),'2024'!$AD$5:$AD$178,"<"&DATE(2028,1,1))) | D18: =IF(2027>YEAR(TODAY()),"",COUNTIFS('2024'!$AG$5:$AG$178,">="&DATE(2027,1,1),'2024'!$AG$5:$AG$178,"<"&DATE(2028,1,1))) | E18: =IF(2027>YEAR(TODAY()),"",SUMIFS('2024'!$X$5:$X$178,'2024'!$AG$5:$AG$178,">="&DATE(2027,1,1),'2024'!$AG$5:$AG$178,"<"&DATE(2028,1,1))) | F18: =IF(N(D18)=0,"",E18/D18) | G18: =IF(E18="","",E18/2) | H18: =IF(2027>YEAR(TODAY()),"",SUMIFS('2024'!$V$5:$V$178,'2024'!$AG$5:$AG$178,">="&DATE(2027,1,1),'2024'!$AG$5:$AG$178,"<"&DATE(2028,1,1))) | I18: =IF(N(D18)=0,"",(SUMIFS('2024'!$AH$5:$AH$178,'2024'!$AG$5:$AG$178,">="&DATE(2027,1,1),'2024'!$AG$5:$AG$178,"<"&DATE(2028,1,1)))/D18) | J18: =IF(N(D18)=0,"",(SUMIFS('2024'!$AI$5:$AI$178,'2024'!$AG$5:$AG$178,">="&DATE(2027,1,1),'2024'!$AG$5:$AG$178,"<"&DATE(2028,1,1)))/D18)
B19: =IF(2028>YEAR(TODAY()),"",2028) | C19: =IF(2028>YEAR(TODAY()),"",COUNTIFS('2024'!$AD$5:$AD$178,">="&DATE(2028,1,1),'2024'!$AD$5:$AD$178,"<"&DATE(2029,1,1))) | D19: =IF(2028>YEAR(TODAY()),"",COUNTIFS('2024'!$AG$5:$AG$178,">="&DATE(2028,1,1),'2024'!$AG$5:$AG$178,"<"&DATE(2029,1,1))) | E19: =IF(2028>YEAR(TODAY()),"",SUMIFS('2024'!$X$5:$X$178,'2024'!$AG$5:$AG$178,">="&DATE(2028,1,1),'2024'!$AG$5:$AG$178,"<"&DATE(2029,1,1))) | F19: =IF(N(D19)=0,"",E19/D19) | G19: =IF(E19="","",E19/2) | H19: =IF(2028>YEAR(TODAY()),"",SUMIFS('2024'!$V$5:$V$178,'2024'!$AG$5:$AG$178,">="&DATE(2028,1,1),'2024'!$AG$5:$AG$178,"<"&DATE(2029,1,1))) | I19: =IF(N(D19)=0,"",(SUMIFS('2024'!$AH$5:$AH$178,'2024'!$AG$5:$AG$178,">="&DATE(2028,1,1),'2024'!$AG$5:$AG$178,"<"&DATE(2029,1,1)))/D19) | J19: =IF(N(D19)=0,"",(SUMIFS('2024'!$AI$5:$AI$178,'2024'!$AG$5:$AG$178,">="&DATE(2028,1,1),'2024'!$AG$5:$AG$178,"<"&DATE(2029,1,1)))/D19)
B20: =IF(2029>YEAR(TODAY()),"",2029) | C20: =IF(2029>YEAR(TODAY()),"",COUNTIFS('2024'!$AD$5:$AD$178,">="&DATE(2029,1,1),'2024'!$AD$5:$AD$178,"<"&DATE(2030,1,1))) | D20: =IF(2029>YEAR(TODAY()),"",COUNTIFS('2024'!$AG$5:$AG$178,">="&DATE(2029,1,1),'2024'!$AG$5:$AG$178,"<"&DATE(2030,1,1))) | E20: =IF(2029>YEAR(TODAY()),"",SUMIFS('2024'!$X$5:$X$178,'2024'!$AG$5:$AG$178,">="&DATE(2029,1,1),'2024'!$AG$5:$AG$178,"<"&DATE(2030,1,1))) | F20: =IF(N(D20)=0,"",E20/D20) | G20: =IF(E20="","",E20/2) | H20: =IF(2029>YEAR(TODAY()),"",SUMIFS('2024'!$V$5:$V$178,'2024'!$AG$5:$AG$178,">="&DATE(2029,1,1),'2024'!$AG$5:$AG$178,"<"&DATE(2030,1,1))) | I20: =IF(N(D20)=0,"",(SUMIFS('2024'!$AH$5:$AH$178,'2024'!$AG$5:$AG$178,">="&DATE(2029,1,1),'2024'!$AG$5:$AG$178,"<"&DATE(2030,1,1)))/D20) | J20: =IF(N(D20)=0,"",(SUMIFS('2024'!$AI$5:$AI$178,'2024'!$AG$5:$AG$178,">="&DATE(2029,1,1),'2024'!$AG$5:$AG$178,"<"&DATE(2030,1,1)))/D20)
B21: =IF(2030>YEAR(TODAY()),"",2030) | C21: =IF(2030>YEAR(TODAY()),"",COUNTIFS('2024'!$AD$5:$AD$178,">="&DATE(2030,1,1),'2024'!$AD$5:$AD$178,"<"&DATE(2031,1,1))) | D21: =IF(2030>YEAR(TODAY()),"",COUNTIFS('2024'!$AG$5:$AG$178,">="&DATE(2030,1,1),'2024'!$AG$5:$AG$178,"<"&DATE(2031,1,1))) | E21: =IF(2030>YEAR(TODAY()),"",SUMIFS('2024'!$X$5:$X$178,'2024'!$AG$5:$AG$178,">="&DATE(2030,1,1),'2024'!$AG$5:$AG$178,"<"&DATE(2031,1,1))) | F21: =IF(N(D21)=0,"",E21/D21) | G21: =IF(E21="","",E21/2) | H21: =IF(2030>YEAR(TODAY()),"",SUMIFS('2024'!$V$5:$V$178,'2024'!$AG$5:$AG$178,">="&DATE(2030,1,1),'2024'!$AG$5:$AG$178,"<"&DATE(2031,1,1))) | I21: =IF(N(D21)=0,"",(SUMIFS('2024'!$AH$5:$AH$178,'2024'!$AG$5:$AG$178,">="&DATE(2030,1,1),'2024'!$AG$5:$AG$178,"<"&DATE(2031,1,1)))/D21) | J21: =IF(N(D21)=0,"",(SUMIFS('2024'!$AI$5:$AI$178,'2024'!$AG$5:$AG$178,">="&DATE(2030,1,1),'2024'!$AG$5:$AG$178,"<"&DATE(2031,1,1)))/D21)
B22: =IF(2031>YEAR(TODAY()),"",2031) | C22: =IF(2031>YEAR(TODAY()),"",COUNTIFS('2024'!$AD$5:$AD$178,">="&DATE(2031,1,1),'2024'!$AD$5:$AD$178,"<"&DATE(2032,1,1))) | D22: =IF(2031>YEAR(TODAY()),"",COUNTIFS('2024'!$AG$5:$AG$178,">="&DATE(2031,1,1),'2024'!$AG$5:$AG$178,"<"&DATE(2032,1,1))) | E22: =IF(2031>YEAR(TODAY()),"",SUMIFS('2024'!$X$5:$X$178,'2024'!$AG$5:$AG$178,">="&DATE(2031,1,1),'2024'!$AG$5:$AG$178,"<"&DATE(2032,1,1))) | F22: =IF(N(D22)=0,"",E22/D22) | G22: =IF(E22="","",E22/2) | H22: =IF(2031>YEAR(TODAY()),"",SUMIFS('2024'!$V$5:$V$178,'2024'!$AG$5:$AG$178,">="&DATE(2031,1,1),'2024'!$AG$5:$AG$178,"<"&DATE(2032,1,1))) | I22: =IF(N(D22)=0,"",(SUMIFS('2024'!$AH$5:$AH$178,'2024'!$AG$5:$AG$178,">="&DATE(2031,1,1),'2024'!$AG$5:$AG$178,"<"&DATE(2032,1,1)))/D22) | J22: =IF(N(D22)=0,"",(SUMIFS('2024'!$AI$5:$AI$178,'2024'!$AG$5:$AG$178,">="&DATE(2031,1,1),'2024'!$AG$5:$AG$178,"<"&DATE(2032,1,1)))/D22)
B23: =IF(2032>YEAR(TODAY()),"",2032) | C23: =IF(2032>YEAR(TODAY()),"",COUNTIFS('2024'!$AD$5:$AD$178,">="&DATE(2032,1,1),'2024'!$AD$5:$AD$178,"<"&DATE(2033,1,1))) | D23: =IF(2032>YEAR(TODAY()),"",COUNTIFS('2024'!$AG$5:$AG$178,">="&DATE(2032,1,1),'2024'!$AG$5:$AG$178,"<"&DATE(2033,1,1))) | E23: =IF(2032>YEAR(TODAY()),"",SUMIFS('2024'!$X$5:$X$178,'2024'!$AG$5:$AG$178,">="&DATE(2032,1,1),'2024'!$AG$5:$AG$178,"<"&DATE(2033,1,1))) | F23: =IF(N(D23)=0,"",E23/D23) | G23: =IF(E23="","",E23/2) | H23: =IF(2032>YEAR(TODAY()),"",SUMIFS('2024'!$V$5:$V$178,'2024'!$AG$5:$AG$178,">="&DATE(2032,1,1),'2024'!$AG$5:$AG$178,"<"&DATE(2033,1,1))) | I23: =IF(N(D23)=0,"",(SUMIFS('2024'!$AH$5:$AH$178,'2024'!$AG$5:$AG$178,">="&DATE(2032,1,1),'2024'!$AG$5:$AG$178,"<"&DATE(2033,1,1)))/D23) | J23: =IF(N(D23)=0,"",(SUMIFS('2024'!$AI$5:$AI$178,'2024'!$AG$5:$AG$178,">="&DATE(2032,1,1),'2024'!$AG$5:$AG$178,"<"&DATE(2033,1,1)))/D23)
B24: =IF(2033>YEAR(TODAY()),"",2033) | C24: =IF(2033>YEAR(TODAY()),"",COUNTIFS('2024'!$AD$5:$AD$178,">="&DATE(2033,1,1),'2024'!$AD$5:$AD$178,"<"&DATE(2034,1,1))) | D24: =IF(2033>YEAR(TODAY()),"",COUNTIFS('2024'!$AG$5:$AG$178,">="&DATE(2033,1,1),'2024'!$AG$5:$AG$178,"<"&DATE(2034,1,1))) | E24: =IF(2033>YEAR(TODAY()),"",SUMIFS('2024'!$X$5:$X$178,'2024'!$AG$5:$AG$178,">="&DATE(2033,1,1),'2024'!$AG$5:$AG$178,"<"&DATE(2034,1,1))) | F24: =IF(N(D24)=0,"",E24/D24) | G24: =IF(E24="","",E24/2) | H24: =IF(2033>YEAR(TODAY()),"",SUMIFS('2024'!$V$5:$V$178,'2024'!$AG$5:$AG$178,">="&DATE(2033,1,1),'2024'!$AG$5:$AG$178,"<"&DATE(2034,1,1))) | I24: =IF(N(D24)=0,"",(SUMIFS('2024'!$AH$5:$AH$178,'2024'!$AG$5:$AG$178,">="&DATE(2033,1,1),'2024'!$AG$5:$AG$178,"<"&DATE(2034,1,1)))/D24) | J24: =IF(N(D24)=0,"",(SUMIFS('2024'!$AI$5:$AI$178,'2024'!$AG$5:$AG$178,">="&DATE(2033,1,1),'2024'!$AG$5:$AG$178,"<"&DATE(2034,1,1)))/D24)
B25: =IF(2034>YEAR(TODAY()),"",2034) | C25: =IF(2034>YEAR(TODAY()),"",COUNTIFS('2024'!$AD$5:$AD$178,">="&DATE(2034,1,1),'2024'!$AD$5:$AD$178,"<"&DATE(2035,1,1))) | D25: =IF(2034>YEAR(TODAY()),"",COUNTIFS('2024'!$AG$5:$AG$178,">="&DATE(2034,1,1),'2024'!$AG$5:$AG$178,"<"&DATE(2035,1,1))) | E25: =IF(2034>YEAR(TODAY()),"",SUMIFS('2024'!$X$5:$X$178,'2024'!$AG$5:$AG$178,">="&DATE(2034,1,1),'2024'!$AG$5:$AG$178,"<"&DATE(2035,1,1))) | F25: =IF(N(D25)=0,"",E25/D25) | G25: =IF(E25="","",E25/2) | H25: =IF(2034>YEAR(TODAY()),"",SUMIFS('2024'!$V$5:$V$178,'2024'!$AG$5:$AG$178,">="&DATE(2034,1,1),'2024'!$AG$5:$AG$178,"<"&DATE(2035,1,1))) | I25: =IF(N(D25)=0,"",(SUMIFS('2024'!$AH$5:$AH$178,'2024'!$AG$5:$AG$178,">="&DATE(2034,1,1),'2024'!$AG$5:$AG$178,"<"&DATE(2035,1,1)))/D25) | J25: =IF(N(D25)=0,"",(SUMIFS('2024'!$AI$5:$AI$178,'2024'!$AG$5:$AG$178,">="&DATE(2034,1,1),'2024'!$AG$5:$AG$178,"<"&DATE(2035,1,1)))/D25)
B26: =IF(2035>YEAR(TODAY()),"",2035) | C26: =IF(2035>YEAR(TODAY()),"",COUNTIFS('2024'!$AD$5:$AD$178,">="&DATE(2035,1,1),'2024'!$AD$5:$AD$178,"<"&DATE(2036,1,1))) | D26: =IF(2035>YEAR(TODAY()),"",COUNTIFS('2024'!$AG$5:$AG$178,">="&DATE(2035,1,1),'2024'!$AG$5:$AG$178,"<"&DATE(2036,1,1))) | E26: =IF(2035>YEAR(TODAY()),"",SUMIFS('2024'!$X$5:$X$178,'2024'!$AG$5:$AG$178,">="&DATE(2035,1,1),'2024'!$AG$5:$AG$178,"<"&DATE(2036,1,1))) | F26: =IF(N(D26)=0,"",E26/D26) | G26: =IF(E26="","",E26/2) | H26: =IF(2035>YEAR(TODAY()),"",SUMIFS('2024'!$V$5:$V$178,'2024'!$AG$5:$AG$178,">="&DATE(2035,1,1),'2024'!$AG$5:$AG$178,"<"&DATE(2036,1,1))) | I26: =IF(N(D26)=0,"",(SUMIFS('2024'!$AH$5:$AH$178,'2024'!$AG$5:$AG$178,">="&DATE(2035,1,1),'2024'!$AG$5:$AG$178,"<"&DATE(2036,1,1)))/D26) | J26: =IF(N(D26)=0,"",(SUMIFS('2024'!$AI$5:$AI$178,'2024'!$AG$5:$AG$178,">="&DATE(2035,1,1),'2024'!$AG$5:$AG$178,"<"&DATE(2036,1,1)))/D26)
B27: All years | C27: =SUM(C15:C26) | D27: =SUM(D15:D26) | E27: =SUM(E15:E26) | F27: =IF(D27=0,"",E27/D27) | G27: =E27/2 | H27: =SUM(H15:H26)
B29: By month — the current month is highlighted
B30: Month | C30: Cars bought | D30: Cars sold | E30: Profit | F30: Avg profit / car | G30: Half profit (each of you) | H30: Sales total | I30: Avg days online | J30: Avg days bought → sold
B31: =IF(DATE(2024,1,1)>TODAY(),"",DATE(2024,1,1)) | C31: =IF(DATE(2024,1,1)>TODAY(),"",COUNTIFS('2024'!$AD$5:$AD$178,">="&DATE(2024,1,1),'2024'!$AD$5:$AD$178,"<"&EDATE(DATE(2024,1,1),1))) | D31: =IF(DATE(2024,1,1)>TODAY(),"",COUNTIFS('2024'!$AG$5:$AG$178,">="&DATE(2024,1,1),'2024'!$AG$5:$AG$178,"<"&EDATE(DATE(2024,1,1),1))) | E31: =IF(DATE(2024,1,1)>TODAY(),"",SUMIFS('2024'!$X$5:$X$178,'2024'!$AG$5:$AG$178,">="&DATE(2024,1,1),'2024'!$AG$5:$AG$178,"<"&EDATE(DATE(2024,1,1),1))) | F31: =IF(N(D31)=0,"",E31/D31) | G31: =IF(E31="","",E31/2) | H31: =IF(DATE(2024,1,1)>TODAY(),"",SUMIFS('2024'!$V$5:$V$178,'2024'!$AG$5:$AG$178,">="&DATE(2024,1,1),'2024'!$AG$5:$AG$178,"<"&EDATE(DATE(2024,1,1),1))) | I31: =IF(N(D31)=0,"",(SUMIFS('2024'!$AH$5:$AH$178,'2024'!$AG$5:$AG$178,">="&DATE(2024,1,1),'2024'!$AG$5:$AG$178,"<"&EDATE(DATE(2024,1,1),1)))/D31) | J31: =IF(N(D31)=0,"",(SUMIFS('2024'!$AI$5:$AI$178,'2024'!$AG$5:$AG$178,">="&DATE(2024,1,1),'2024'!$AG$5:$AG$178,"<"&EDATE(DATE(2024,1,1),1)))/D31)
B32: =IF(DATE(2024,2,1)>TODAY(),"",DATE(2024,2,1)) | C32: =IF(DATE(2024,2,1)>TODAY(),"",COUNTIFS('2024'!$AD$5:$AD$178,">="&DATE(2024,2,1),'2024'!$AD$5:$AD$178,"<"&EDATE(DATE(2024,2,1),1))) | D32: =IF(DATE(2024,2,1)>TODAY(),"",COUNTIFS('2024'!$AG$5:$AG$178,">="&DATE(2024,2,1),'2024'!$AG$5:$AG$178,"<"&EDATE(DATE(2024,2,1),1))) | E32: =IF(DATE(2024,2,1)>TODAY(),"",SUMIFS('2024'!$X$5:$X$178,'2024'!$AG$5:$AG$178,">="&DATE(2024,2,1),'2024'!$AG$5:$AG$178,"<"&EDATE(DATE(2024,2,1),1))) | F32: =IF(N(D32)=0,"",E32/D32) | G32: =IF(E32="","",E32/2) | H32: =IF(DATE(2024,2,1)>TODAY(),"",SUMIFS('2024'!$V$5:$V$178,'2024'!$AG$5:$AG$178,">="&DATE(2024,2,1),'2024'!$AG$5:$AG$178,"<"&EDATE(DATE(2024,2,1),1))) | I32: =IF(N(D32)=0,"",(SUMIFS('2024'!$AH$5:$AH$178,'2024'!$AG$5:$AG$178,">="&DATE(2024,2,1),'2024'!$AG$5:$AG$178,"<"&EDATE(DATE(2024,2,1),1)))/D32) | J32: =IF(N(D32)=0,"",(SUMIFS('2024'!$AI$5:$AI$178,'2024'!$AG$5:$AG$178,">="&DATE(2024,2,1),'2024'!$AG$5:$AG$178,"<"&EDATE(DATE(2024,2,1),1)))/D32)
B33: =IF(DATE(2024,3,1)>TODAY(),"",DATE(2024,3,1)) | C33: =IF(DATE(2024,3,1)>TODAY(),"",COUNTIFS('2024'!$AD$5:$AD$178,">="&DATE(2024,3,1),'2024'!$AD$5:$AD$178,"<"&EDATE(DATE(2024,3,1),1))) | D33: =IF(DATE(2024,3,1)>TODAY(),"",COUNTIFS('2024'!$AG$5:$AG$178,">="&DATE(2024,3,1),'2024'!$AG$5:$AG$178,"<"&EDATE(DATE(2024,3,1),1))) | E33: =IF(DATE(2024,3,1)>TODAY(),"",SUMIFS('2024'!$X$5:$X$178,'2024'!$AG$5:$AG$178,">="&DATE(2024,3,1),'2024'!$AG$5:$AG$178,"<"&EDATE(DATE(2024,3,1),1))) | F33: =IF(N(D33)=0,"",E33/D33) | G33: =IF(E33="","",E33/2) | H33: =IF(DATE(2024,3,1)>TODAY(),"",SUMIFS('2024'!$V$5:$V$178,'2024'!$AG$5:$AG$178,">="&DATE(2024,3,1),'2024'!$AG$5:$AG$178,"<"&EDATE(DATE(2024,3,1),1))) | I33: =IF(N(D33)=0,"",(SUMIFS('2024'!$AH$5:$AH$178,'2024'!$AG$5:$AG$178,">="&DATE(2024,3,1),'2024'!$AG$5:$AG$178,"<"&EDATE(DATE(2024,3,1),1)))/D33) | J33: =IF(N(D33)=0,"",(SUMIFS('2024'!$AI$5:$AI$178,'2024'!$AG$5:$AG$178,">="&DATE(2024,3,1),'2024'!$AG$5:$AG$178,"<"&EDATE(DATE(2024,3,1),1)))/D33)
B34: =IF(DATE(2024,4,1)>TODAY(),"",DATE(2024,4,1)) | C34: =IF(DATE(2024,4,1)>TODAY(),"",COUNTIFS('2024'!$AD$5:$AD$178,">="&DATE(2024,4,1),'2024'!$AD$5:$AD$178,"<"&EDATE(DATE(2024,4,1),1))) | D34: =IF(DATE(2024,4,1)>TODAY(),"",COUNTIFS('2024'!$AG$5:$AG$178,">="&DATE(2024,4,1),'2024'!$AG$5:$AG$178,"<"&EDATE(DATE(2024,4,1),1))) | E34: =IF(DATE(2024,4,1)>TODAY(),"",SUMIFS('2024'!$X$5:$X$178,'2024'!$AG$5:$AG$178,">="&DATE(2024,4,1),'2024'!$AG$5:$AG$178,"<"&EDATE(DATE(2024,4,1),1))) | F34: =IF(N(D34)=0,"",E34/D34) | G34: =IF(E34="","",E34/2) | H34: =IF(DATE(2024,4,1)>TODAY(),"",SUMIFS('2024'!$V$5:$V$178,'2024'!$AG$5:$AG$178,">="&DATE(2024,4,1),'2024'!$AG$5:$AG$178,"<"&EDATE(DATE(2024,4,1),1))) | I34: =IF(N(D34)=0,"",(SUMIFS('2024'!$AH$5:$AH$178,'2024'!$AG$5:$AG$178,">="&DATE(2024,4,1),'2024'!$AG$5:$AG$178,"<"&EDATE(DATE(2024,4,1),1)))/D34) | J34: =IF(N(D34)=0,"",(SUMIFS('2024'!$AI$5:$AI$178,'2024'!$AG$5:$AG$178,">="&DATE(2024,4,1),'2024'!$AG$5:$AG$178,"<"&EDATE(DATE(2024,4,1),1)))/D34)
B35: =IF(DATE(2024,5,1)>TODAY(),"",DATE(2024,5,1)) | C35: =IF(DATE(2024,5,1)>TODAY(),"",COUNTIFS('2024'!$AD$5:$AD$178,">="&DATE(2024,5,1),'2024'!$AD$5:$AD$178,"<"&EDATE(DATE(2024,5,1),1))) | D35: =IF(DATE(2024,5,1)>TODAY(),"",COUNTIFS('2024'!$AG$5:$AG$178,">="&DATE(2024,5,1),'2024'!$AG$5:$AG$178,"<"&EDATE(DATE(2024,5,1),1))) | E35: =IF(DATE(2024,5,1)>TODAY(),"",SUMIFS('2024'!$X$5:$X$178,'2024'!$AG$5:$AG$178,">="&DATE(2024,5,1),'2024'!$AG$5:$AG$178,"<"&EDATE(DATE(2024,5,1),1))) | F35: =IF(N(D35)=0,"",E35/D35) | G35: =IF(E35="","",E35/2) | H35: =IF(DATE(2024,5,1)>TODAY(),"",SUMIFS('2024'!$V$5:$V$178,'2024'!$AG$5:$AG$178,">="&DATE(2024,5,1),'2024'!$AG$5:$AG$178,"<"&EDATE(DATE(2024,5,1),1))) | I35: =IF(N(D35)=0,"",(SUMIFS('2024'!$AH$5:$AH$178,'2024'!$AG$5:$AG$178,">="&DATE(2024,5,1),'2024'!$AG$5:$AG$178,"<"&EDATE(DATE(2024,5,1),1)))/D35) | J35: =IF(N(D35)=0,"",(SUMIFS('2024'!$AI$5:$AI$178,'2024'!$AG$5:$AG$178,">="&DATE(2024,5,1),'2024'!$AG$5:$AG$178,"<"&EDATE(DATE(2024,5,1),1)))/D35)
B36: =IF(DATE(2024,6,1)>TODAY(),"",DATE(2024,6,1)) | C36: =IF(DATE(2024,6,1)>TODAY(),"",COUNTIFS('2024'!$AD$5:$AD$178,">="&DATE(2024,6,1),'2024'!$AD$5:$AD$178,"<"&EDATE(DATE(2024,6,1),1))) | D36: =IF(DATE(2024,6,1)>TODAY(),"",COUNTIFS('2024'!$AG$5:$AG$178,">="&DATE(2024,6,1),'2024'!$AG$5:$AG$178,"<"&EDATE(DATE(2024,6,1),1))) | E36: =IF(DATE(2024,6,1)>TODAY(),"",SUMIFS('2024'!$X$5:$X$178,'2024'!$AG$5:$AG$178,">="&DATE(2024,6,1),'2024'!$AG$5:$AG$178,"<"&EDATE(DATE(2024,6,1),1))) | F36: =IF(N(D36)=0,"",E36/D36) | G36: =IF(E36="","",E36/2) | H36: =IF(DATE(2024,6,1)>TODAY(),"",SUMIFS('2024'!$V$5:$V$178,'2024'!$AG$5:$AG$178,">="&DATE(2024,6,1),'2024'!$AG$5:$AG$178,"<"&EDATE(DATE(2024,6,1),1))) | I36: =IF(N(D36)=0,"",(SUMIFS('2024'!$AH$5:$AH$178,'2024'!$AG$5:$AG$178,">="&DATE(2024,6,1),'2024'!$AG$5:$AG$178,"<"&EDATE(DATE(2024,6,1),1)))/D36) | J36: =IF(N(D36)=0,"",(SUMIFS('2024'!$AI$5:$AI$178,'2024'!$AG$5:$AG$178,">="&DATE(2024,6,1),'2024'!$AG$5:$AG$178,"<"&EDATE(DATE(2024,6,1),1)))/D36)
B37: =IF(DATE(2024,7,1)>TODAY(),"",DATE(2024,7,1)) | C37: =IF(DATE(2024,7,1)>TODAY(),"",COUNTIFS('2024'!$AD$5:$AD$178,">="&DATE(2024,7,1),'2024'!$AD$5:$AD$178,"<"&EDATE(DATE(2024,7,1),1))) | D37: =IF(DATE(2024,7,1)>TODAY(),"",COUNTIFS('2024'!$AG$5:$AG$178,">="&DATE(2024,7,1),'2024'!$AG$5:$AG$178,"<"&EDATE(DATE(2024,7,1),1))) | E37: =IF(DATE(2024,7,1)>TODAY(),"",SUMIFS('2024'!$X$5:$X$178,'2024'!$AG$5:$AG$178,">="&DATE(2024,7,1),'2024'!$AG$5:$AG$178,"<"&EDATE(DATE(2024,7,1),1))) | F37: =IF(N(D37)=0,"",E37/D37) | G37: =IF(E37="","",E37/2) | H37: =IF(DATE(2024,7,1)>TODAY(),"",SUMIFS('2024'!$V$5:$V$178,'2024'!$AG$5:$AG$178,">="&DATE(2024,7,1),'2024'!$AG$5:$AG$178,"<"&EDATE(DATE(2024,7,1),1))) | I37: =IF(N(D37)=0,"",(SUMIFS('2024'!$AH$5:$AH$178,'2024'!$AG$5:$AG$178,">="&DATE(2024,7,1),'2024'!$AG$5:$AG$178,"<"&EDATE(DATE(2024,7,1),1)))/D37) | J37: =IF(N(D37)=0,"",(SUMIFS('2024'!$AI$5:$AI$178,'2024'!$AG$5:$AG$178,">="&DATE(2024,7,1),'2024'!$AG$5:$AG$178,"<"&EDATE(DATE(2024,7,1),1)))/D37)
B38: =IF(DATE(2024,8,1)>TODAY(),"",DATE(2024,8,1)) | C38: =IF(DATE(2024,8,1)>TODAY(),"",COUNTIFS('2024'!$AD$5:$AD$178,">="&DATE(2024,8,1),'2024'!$AD$5:$AD$178,"<"&EDATE(DATE(2024,8,1),1))) | D38: =IF(DATE(2024,8,1)>TODAY(),"",COUNTIFS('2024'!$AG$5:$AG$178,">="&DATE(2024,8,1),'2024'!$AG$5:$AG$178,"<"&EDATE(DATE(2024,8,1),1))) | E38: =IF(DATE(2024,8,1)>TODAY(),"",SUMIFS('2024'!$X$5:$X$178,'2024'!$AG$5:$AG$178,">="&DATE(2024,8,1),'2024'!$AG$5:$AG$178,"<"&EDATE(DATE(2024,8,1),1))) | F38: =IF(N(D38)=0,"",E38/D38) | G38: =IF(E38="","",E38/2) | H38: =IF(DATE(2024,8,1)>TODAY(),"",SUMIFS('2024'!$V$5:$V$178,'2024'!$AG$5:$AG$178,">="&DATE(2024,8,1),'2024'!$AG$5:$AG$178,"<"&EDATE(DATE(2024,8,1),1))) | I38: =IF(N(D38)=0,"",(SUMIFS('2024'!$AH$5:$AH$178,'2024'!$AG$5:$AG$178,">="&DATE(2024,8,1),'2024'!$AG$5:$AG$178,"<"&EDATE(DATE(2024,8,1),1)))/D38) | J38: =IF(N(D38)=0,"",(SUMIFS('2024'!$AI$5:$AI$178,'2024'!$AG$5:$AG$178,">="&DATE(2024,8,1),'2024'!$AG$5:$AG$178,"<"&EDATE(DATE(2024,8,1),1)))/D38)
B39: =IF(DATE(2024,9,1)>TODAY(),"",DATE(2024,9,1)) | C39: =IF(DATE(2024,9,1)>TODAY(),"",COUNTIFS('2024'!$AD$5:$AD$178,">="&DATE(2024,9,1),'2024'!$AD$5:$AD$178,"<"&EDATE(DATE(2024,9,1),1))) | D39: =IF(DATE(2024,9,1)>TODAY(),"",COUNTIFS('2024'!$AG$5:$AG$178,">="&DATE(2024,9,1),'2024'!$AG$5:$AG$178,"<"&EDATE(DATE(2024,9,1),1))) | E39: =IF(DATE(2024,9,1)>TODAY(),"",SUMIFS('2024'!$X$5:$X$178,'2024'!$AG$5:$AG$178,">="&DATE(2024,9,1),'2024'!$AG$5:$AG$178,"<"&EDATE(DATE(2024,9,1),1))) | F39: =IF(N(D39)=0,"",E39/D39) | G39: =IF(E39="","",E39/2) | H39: =IF(DATE(2024,9,1)>TODAY(),"",SUMIFS('2024'!$V$5:$V$178,'2024'!$AG$5:$AG$178,">="&DATE(2024,9,1),'2024'!$AG$5:$AG$178,"<"&EDATE(DATE(2024,9,1),1))) | I39: =IF(N(D39)=0,"",(SUMIFS('2024'!$AH$5:$AH$178,'2024'!$AG$5:$AG$178,">="&DATE(2024,9,1),'2024'!$AG$5:$AG$178,"<"&EDATE(DATE(2024,9,1),1)))/D39) | J39: =IF(N(D39)=0,"",(SUMIFS('2024'!$AI$5:$AI$178,'2024'!$AG$5:$AG$178,">="&DATE(2024,9,1),'2024'!$AG$5:$AG$178,"<"&EDATE(DATE(2024,9,1),1)))/D39)
B40: =IF(DATE(2024,10,1)>TODAY(),"",DATE(2024,10,1)) | C40: =IF(DATE(2024,10,1)>TODAY(),"",COUNTIFS('2024'!$AD$5:$AD$178,">="&DATE(2024,10,1),'2024'!$AD$5:$AD$178,"<"&EDATE(DATE(2024,10,1),1))) | D40: =IF(DATE(2024,10,1)>TODAY(),"",COUNTIFS('2024'!$AG$5:$AG$178,">="&DATE(2024,10,1),'2024'!$AG$5:$AG$178,"<"&EDATE(DATE(2024,10,1),1))) | E40: =IF(DATE(2024,10,1)>TODAY(),"",SUMIFS('2024'!$X$5:$X$178,'2024'!$AG$5:$AG$178,">="&DATE(2024,10,1),'2024'!$AG$5:$AG$178,"<"&EDATE(DATE(2024,10,1),1))) | F40: =IF(N(D40)=0,"",E40/D40) | G40: =IF(E40="","",E40/2) | H40: =IF(DATE(2024,10,1)>TODAY(),"",SUMIFS('2024'!$V$5:$V$178,'2024'!$AG$5:$AG$178,">="&DATE(2024,10,1),'2024'!$AG$5:$AG$178,"<"&EDATE(DATE(2024,10,1),1))) | I40: =IF(N(D40)=0,"",(SUMIFS('2024'!$AH$5:$AH$178,'2024'!$AG$5:$AG$178,">="&DATE(2024,10,1),'2024'!$AG$5:$AG$178,"<"&EDATE(DATE(2024,10,1),1)))/D40) | J40: =IF(N(D40)=0,"",(SUMIFS('2024'!$AI$5:$AI$178,'2024'!$AG$5:$AG$178,">="&DATE(2024,10,1),'2024'!$AG$5:$AG$178,"<"&EDATE(DATE(2024,10,1),1)))/D40)
B41: =IF(DATE(2024,11,1)>TODAY(),"",DATE(2024,11,1)) | C41: =IF(DATE(2024,11,1)>TODAY(),"",COUNTIFS('2024'!$AD$5:$AD$178,">="&DATE(2024,11,1),'2024'!$AD$5:$AD$178,"<"&EDATE(DATE(2024,11,1),1))) | D41: =IF(DATE(2024,11,1)>TODAY(),"",COUNTIFS('2024'!$AG$5:$AG$178,">="&DATE(2024,11,1),'2024'!$AG$5:$AG$178,"<"&EDATE(DATE(2024,11,1),1))) | E41: =IF(DATE(2024,11,1)>TODAY(),"",SUMIFS('2024'!$X$5:$X$178,'2024'!$AG$5:$AG$178,">="&DATE(2024,11,1),'2024'!$AG$5:$AG$178,"<"&EDATE(DATE(2024,11,1),1))) | F41: =IF(N(D41)=0,"",E41/D41) | G41: =IF(E41="","",E41/2) | H41: =IF(DATE(2024,11,1)>TODAY(),"",SUMIFS('2024'!$V$5:$V$178,'2024'!$AG$5:$AG$178,">="&DATE(2024,11,1),'2024'!$AG$5:$AG$178,"<"&EDATE(DATE(2024,11,1),1))) | I41: =IF(N(D41)=0,"",(SUMIFS('2024'!$AH$5:$AH$178,'2024'!$AG$5:$AG$178,">="&DATE(2024,11,1),'2024'!$AG$5:$AG$178,"<"&EDATE(DATE(2024,11,1),1)))/D41) | J41: =IF(N(D41)=0,"",(SUMIFS('2024'!$AI$5:$AI$178,'2024'!$AG$5:$AG$178,">="&DATE(2024,11,1),'2024'!$AG$5:$AG$178,"<"&EDATE(DATE(2024,11,1),1)))/D41)
B42: =IF(DATE(2024,12,1)>TODAY(),"",DATE(2024,12,1)) | C42: =IF(DATE(2024,12,1)>TODAY(),"",COUNTIFS('2024'!$AD$5:$AD$178,">="&DATE(2024,12,1),'2024'!$AD$5:$AD$178,"<"&EDATE(DATE(2024,12,1),1))) | D42: =IF(DATE(2024,12,1)>TODAY(),"",COUNTIFS('2024'!$AG$5:$AG$178,">="&DATE(2024,12,1),'2024'!$AG$5:$AG$178,"<"&EDATE(DATE(2024,12,1),1))) | E42: =IF(DATE(2024,12,1)>TODAY(),"",SUMIFS('2024'!$X$5:$X$178,'2024'!$AG$5:$AG$178,">="&DATE(2024,12,1),'2024'!$AG$5:$AG$178,"<"&EDATE(DATE(2024,12,1),1))) | F42: =IF(N(D42)=0,"",E42/D42) | G42: =IF(E42="","",E42/2) | H42: =IF(DATE(2024,12,1)>TODAY(),"",SUMIFS('2024'!$V$5:$V$178,'2024'!$AG$5:$AG$178,">="&DATE(2024,12,1),'2024'!$AG$5:$AG$178,"<"&EDATE(DATE(2024,12,1),1))) | I42: =IF(N(D42)=0,"",(SUMIFS('2024'!$AH$5:$AH$178,'2024'!$AG$5:$AG$178,">="&DATE(2024,12,1),'2024'!$AG$5:$AG$178,"<"&EDATE(DATE(2024,12,1),1)))/D42) | J42: =IF(N(D42)=0,"",(SUMIFS('2024'!$AI$5:$AI$178,'2024'!$AG$5:$AG$178,">="&DATE(2024,12,1),'2024'!$AG$5:$AG$178,"<"&EDATE(DATE(2024,12,1),1)))/D42)
B43: =IF(DATE(2025,1,1)>TODAY(),"",DATE(2025,1,1)) | C43: =IF(DATE(2025,1,1)>TODAY(),"",COUNTIFS('2024'!$AD$5:$AD$178,">="&DATE(2025,1,1),'2024'!$AD$5:$AD$178,"<"&EDATE(DATE(2025,1,1),1))) | D43: =IF(DATE(2025,1,1)>TODAY(),"",COUNTIFS('2024'!$AG$5:$AG$178,">="&DATE(2025,1,1),'2024'!$AG$5:$AG$178,"<"&EDATE(DATE(2025,1,1),1))) | E43: =IF(DATE(2025,1,1)>TODAY(),"",SUMIFS('2024'!$X$5:$X$178,'2024'!$AG$5:$AG$178,">="&DATE(2025,1,1),'2024'!$AG$5:$AG$178,"<"&EDATE(DATE(2025,1,1),1))) | F43: =IF(N(D43)=0,"",E43/D43) | G43: =IF(E43="","",E43/2) | H43: =IF(DATE(2025,1,1)>TODAY(),"",SUMIFS('2024'!$V$5:$V$178,'2024'!$AG$5:$AG$178,">="&DATE(2025,1,1),'2024'!$AG$5:$AG$178,"<"&EDATE(DATE(2025,1,1),1))) | I43: =IF(N(D43)=0,"",(SUMIFS('2024'!$AH$5:$AH$178,'2024'!$AG$5:$AG$178,">="&DATE(2025,1,1),'2024'!$AG$5:$AG$178,"<"&EDATE(DATE(2025,1,1),1)))/D43) | J43: =IF(N(D43)=0,"",(SUMIFS('2024'!$AI$5:$AI$178,'2024'!$AG$5:$AG$178,">="&DATE(2025,1,1),'2024'!$AG$5:$AG$178,"<"&EDATE(DATE(2025,1,1),1)))/D43)
B44: =IF(DATE(2025,2,1)>TODAY(),"",DATE(2025,2,1)) | C44: =IF(DATE(2025,2,1)>TODAY(),"",COUNTIFS('2024'!$AD$5:$AD$178,">="&DATE(2025,2,1),'2024'!$AD$5:$AD$178,"<"&EDATE(DATE(2025,2,1),1))) | D44: =IF(DATE(2025,2,1)>TODAY(),"",COUNTIFS('2024'!$AG$5:$AG$178,">="&DATE(2025,2,1),'2024'!$AG$5:$AG$178,"<"&EDATE(DATE(2025,2,1),1))) | E44: =IF(DATE(2025,2,1)>TODAY(),"",SUMIFS('2024'!$X$5:$X$178,'2024'!$AG$5:$AG$178,">="&DATE(2025,2,1),'2024'!$AG$5:$AG$178,"<"&EDATE(DATE(2025,2,1),1))) | F44: =IF(N(D44)=0,"",E44/D44) | G44: =IF(E44="","",E44/2) | H44: =IF(DATE(2025,2,1)>TODAY(),"",SUMIFS('2024'!$V$5:$V$178,'2024'!$AG$5:$AG$178,">="&DATE(2025,2,1),'2024'!$AG$5:$AG$178,"<"&EDATE(DATE(2025,2,1),1))) | I44: =IF(N(D44)=0,"",(SUMIFS('2024'!$AH$5:$AH$178,'2024'!$AG$5:$AG$178,">="&DATE(2025,2,1),'2024'!$AG$5:$AG$178,"<"&EDATE(DATE(2025,2,1),1)))/D44) | J44: =IF(N(D44)=0,"",(SUMIFS('2024'!$AI$5:$AI$178,'2024'!$AG$5:$AG$178,">="&DATE(2025,2,1),'2024'!$AG$5:$AG$178,"<"&EDATE(DATE(2025,2,1),1)))/D44)
...

Sheet 2024
A1: Empty placeholder. Copy the Statistics tab into your AUTOBONO sheet (right-click the tab → Copy to → Existing spreadsheet); there it reads your real 2024 tab.
