Workbook

Sheet Read me
B2: AUTOBONO — Car database (clean version)
B3: Built 07.10.2026 from your AUTOBONO Google Sheet ("2023" + "2024" tabs, data as of 25.07.2026). 148 cars imported. Your original sheet is not changed.
B5: THE TABS
B6: Summary — stock, money tied up, profit per year and brand, per-partner split. Fully automatic.
B7: Cars — ONE row per car, ever. Never start a new tab for a new year; filter by date instead.
B8: Expenses — ONE row per bill (transport, repair, tyres, ads…), with the Car ID. Adds up into "Extra costs" on Cars.
B9: Check these — problems I found in the old data (missing dates, profits that do not add up). Fix them, then delete the line.
B10: Lists — the values for every dropdown. Add a new brand or country here, never type it freely.
B12: HOW TO USE THE CARS TAB
B13: • Dark-blue headers = you type. Grey headers / grey cells = automatic formulas — never type over them.
B14: • New car bought: next free row, next Car ID (last is 149, so next is 150), Status = STOCK, fill purchase date and price.
B15: • Car sold: change Status to SOLD, fill Sale date, Sale price and "VAT & deductions" (VAT you pay on the sale). Profit appears automatically.
... B32: Because the data is now one clean table per thing, Google AppSheet (appsheet.com, sign in with Google) can turn this sheet into a phone app with forms, photos and dropdowns — without moving the data anywhere.

Sheet Summary
B2: AUTOBONO — Summary
B3: Everything on this tab is calculated from the Cars and Expenses tabs. Do not type here.
B5: Right now
B6: Cars in stock | C6: =COUNTIF(Cars!$B$2:$B$1000,"STOCK") -> 19
B7: Cars reserved | C7: =COUNTIF(Cars!$B$2:$B$1000,"RESERVED") -> 0
B8: Money tied up in stock (total cost, own purchases) | C8: =SUMIFS(Cars!$R$2:$R$1000,Cars!$B$2:$B$1000,"<>SOLD",Cars!$C$2:$C$1000,"Own purchase",Cars!$A$2:$A$1000,"<>") -> 173167.06
B9: Stock cars older than 90 days | C9: =COUNTIFS(Cars!$B$2:$B$1000,"<>SOLD",Cars!$A$2:$A$1000,"<>",Cars!$Z$2:$Z$1000,">90") -> 16
B10: Average days in stock (cars not yet sold) | C10: =IFERROR(AVERAGEIFS(Cars!$Z$2:$Z$1000,Cars!$B$2:$B$1000,"<>SOLD",Cars!$A$2:$A$1000,"<>"),"") -> 181.11111
B11: Cars with missing purchase date | C11: =COUNTIFS(Cars!$A$2:$A$1000,"<>",Cars!$O$2:$O$1000,"") -> 9
B13: Sold cars by year (by sale date)
B14: Year | C14: Cars sold | D14: Profit (€) | E14: Avg profit / car (€) | F14: Avg days in stock | G14: Per partner (€)
B15: 2023 | C15: =COUNTIFS(Cars!$B$2:$B$1000,"SOLD",Cars!$T$2:$T$1000,">="&DATE(2023,1,1),Cars!$T$2:$T$1000,"<"&DATE(2024,1,1)) -> 8 | D15: =SUMIFS(Cars!$X$2:$X$1000,Cars!$B$2:$B$1000,"SOLD",Cars!$T$2:$T$1000,">="&DATE(2023,1,1),Cars!$T$2:$T$1000,"<"&DATE(2024,1,1)) -> 11232.12 | E15: =IF(C15=0,"",D15/C15) -> 1404.015 | F15: =IFERROR(AVERAGEIFS(Cars!$Z$2:$Z$1000,Cars!$B$2:$B$1000,"SOLD",Cars!$T$2:$T$1000,">="&DATE(2023,1,1),Cars!$T$2:$T$1000,"<"&DATE(2024,1,1)),"") | G15: =D15/2 -> 5616.06
B16: 2024 | C16: =COUNTIFS(Cars!$B$2:$B$1000,"SOLD",Cars!$T$2:$T$1000,">="&DATE(2024,1,1),Cars!$T$2:$T$1000,"<"&DATE(2025,1,1)) -> 40 | D16: =SUMIFS(Cars!$X$2:$X$1000,Cars!$B$2:$B$1000,"SOLD",Cars!$T$2:$T$1000,">="&DATE(2024,1,1),Cars!$T$2:$T$1000,"<"&DATE(2025,1,1)) -> 72612 | E16: =IF(C16=0,"",D16/C16) -> 1815.3 | F16: =IFERROR(AVERAGEIFS(Cars!$Z$2:$Z$1000,Cars!$B$2:$B$1000,"SOLD",Cars!$T$2:$T$1000,">="&DATE(2024,1,1),Cars!$T$2:$T$1000,"<"&DATE(2025,1,1)),"") -> 71.775 | G16: =D16/2 -> 36306
B17: 2025 | C17: =COUNTIFS(Cars!$B$2:$B$1000,"SOLD",Cars!$T$2:$T$1000,">="&DATE(2025,1,1),Cars!$T$2:$T$1000,"<"&DATE(2026,1,1)) -> 52 | D17: =SUMIFS(Cars!$X$2:$X$1000,Cars!$B$2:$B$1000,"SOLD",Cars!$T$2:$T$1000,">="&DATE(2025,1,1),Cars!$T$2:$T$1000,"<"&DATE(2026,1,1)) -> 90415 | E17: =IF(C17=0,"",D17/C17) -> 1738.75 | F17: =IFERROR(AVERAGEIFS(Cars!$Z$2:$Z$1000,Cars!$B$2:$B$1000,"SOLD",Cars!$T$2:$T$1000,">="&DATE(2025,1,1),Cars!$T$2:$T$1000,"<"&DATE(2026,1,1)),"") -> 79.480769 | G17: =D17/2 -> 45207.5
B18: 2026 | C18: =COUNTIFS(Cars!$B$2:$B$1000,"SOLD",Cars!$T$2:$T$1000,">="&DATE(2026,1,1),Cars!$T$2:$T$1000,"<"&DATE(2027,1,1)) -> 29 | D18: =SUMIFS(Cars!$X$2:$X$1000,Cars!$B$2:$B$1000,"SOLD",Cars!$T$2:$T$1000,">="&DATE(2026,1,1),Cars!$T$2:$T$1000,"<"&DATE(2027,1,1)) -> 43659 | E18: =IF(C18=0,"",D18/C18) -> 1505.4828 | F18: =IFERROR(AVERAGEIFS(Cars!$Z$2:$Z$1000,Cars!$B$2:$B$1000,"SOLD",Cars!$T$2:$T$1000,">="&DATE(2026,1,1),Cars!$T$2:$T$1000,"<"&DATE(2027,1,1)),"") -> 110.96552 | G18: =D18/2 -> 21829.5
B19: 2027 | C19: =COUNTIFS(Cars!$B$2:$B$1000,"SOLD",Cars!$T$2:$T$1000,">="&DATE(2027,1,1),Cars!$T$2:$T$1000,"<"&DATE(2028,1,1)) -> 0 | D19: =SUMIFS(Cars!$X$2:$X$1000,Cars!$B$2:$B$1000,"SOLD",Cars!$T$2:$T$1000,">="&DATE(2027,1,1),Cars!$T$2:$T$1000,"<"&DATE(2028,1,1)) -> 0 | E19: =IF(C19=0,"",D19/C19) | F19: =IFERROR(AVERAGEIFS(Cars!$Z$2:$Z$1000,Cars!$B$2:$B$1000,"SOLD",Cars!$T$2:$T$1000,">="&DATE(2027,1,1),Cars!$T$2:$T$1000,"<"&DATE(2028,1,1)),"") | G19: =D19/2 -> 0
B20: All years | C20: =SUM(C15:C19) -> 129 | D20: =SUM(D15:D19) -> 217918.12 | E20: =IF(C20=0,"",D20/C20) -> 1689.2878 | G20: =D20/2 -> 108959.06
B22: Sold cars by brand (all years)
B23: Brand | C23: Cars sold | D23: Profit (€) | E23: Avg profit / car (€) | F23: Avg days in stock | G23: In stock now
B24: VW | C24: =COUNTIFS(Cars!$B$2:$B$1000,"SOLD",Cars!$D$2:$D$1000,B24) -> 41 | D24: =SUMIFS(Cars!$X$2:$X$1000,Cars!$B$2:$B$1000,"SOLD",Cars!$D$2:$D$1000,B24) -> 66335 | E24: =IF(C24=0,"",D24/C24) -> 1617.9268 | F24: =IFERROR(AVERAGEIFS(Cars!$Z$2:$Z$1000,Cars!$B$2:$B$1000,"SOLD",Cars!$D$2:$D$1000,B24),"") -> 76.538462 | G24: =COUNTIFS(Cars!$B$2:$B$1000,"<>SOLD",Cars!$D$2:$D$1000,B24) -> 6
B25: Škoda | C25: =COUNTIFS(Cars!$B$2:$B$1000,"SOLD",Cars!$D$2:$D$1000,B25) -> 33 | D25: =SUMIFS(Cars!$X$2:$X$1000,Cars!$B$2:$B$1000,"SOLD",Cars!$D$2:$D$1000,B25) -> 53948.99 | E25: =IF(C25=0,"",D25/C25) -> 1634.8179 | F25: =IFERROR(AVERAGEIFS(Cars!$Z$2:$Z$1000,Cars!$B$2:$B$1000,"SOLD",Cars!$D$2:$D$1000,B25),"") -> 97.6 | G25: =COUNTIFS(Cars!$B$2:$B$1000,"<>SOLD",Cars!$D$2:$D$1000,B25) -> 2
B26: Seat | C26: =COUNTIFS(Cars!$B$2:$B$1000,"SOLD",Cars!$D$2:$D$1000,B26) -> 18 | D26: =SUMIFS(Cars!$X$2:$X$1000,Cars!$B$2:$B$1000,"SOLD",Cars!$D$2:$D$1000,B26) -> 33098 | E26: =IF(C26=0,"",D26/C26) -> 1838.7778 | F26: =IFERROR(AVERAGEIFS(Cars!$Z$2:$Z$1000,Cars!$B$2:$B$1000,"SOLD",Cars!$D$2:$D$1000,B26),"") -> 91.5 | G26: =COUNTIFS(Cars!$B$2:$B$1000,"<>SOLD",Cars!$D$2:$D$1000,B26) -> 4
B27: Audi | C27: =COUNTIFS(Cars!$B$2:$B$1000,"SOLD",Cars!$D$2:$D$1000,B27) -> 12 | D27: =SUMIFS(Cars!$X$2:$X$1000,Cars!$B$2:$B$1000,"SOLD",Cars!$D$2:$D$1000,B27) -> 26413 | E27: =IF(C27=0,"",D27/C27) -> 2201.0833 | F27: =IFERROR(AVERAGEIFS(Cars!$Z$2:$Z$1000,Cars!$B$2:$B$1000,"SOLD",Cars!$D$2:$D$1000,B27),"") -> 60.833333 | G27: =COUNTIFS(Cars!$B$2:$B$1000,"<>SOLD",Cars!$D$2:$D$1000,B27) -> 1
B28: Mercedes-Benz | C28: =COUNTIFS(Cars!$B$2:$B$1000,"SOLD",Cars!$D$2:$D$1000,B28) -> 3 | D28: =SUMIFS(Cars!$X$2:$X$1000,Cars!$B$2:$B$1000,"SOLD",Cars!$D$2:$D$1000,B28) -> 5831 | E28: =IF(C28=0,"",D28/C28) -> 1943.6667 | F28: =IFERROR(AVERAGEIFS(Cars!$Z$2:$Z$1000,Cars!$B$2:$B$1000,"SOLD",Cars!$D$2:$D$1000,B28),"") -> 83.333333 | G28: =COUNTIFS(Cars!$B$2:$B$1000,"<>SOLD",Cars!$D$2:$D$1000,B28) -> 2
B29: Mazda | C29: =COUNTIFS(Cars!$B$2:$B$1000,"SOLD",Cars!$D$2:$D$1000,B29) -> 3 | D29: =SUMIFS(Cars!$X$2:$X$1000,Cars!$B$2:$B$1000,"SOLD",Cars!$D$2:$D$1000,B29) -> 6047.21 | E29: =IF(C29=0,"",D29/C29) -> 2015.7367 | F29: =IFERROR(AVERAGEIFS(Cars!$Z$2:$Z$1000,Cars!$B$2:$B$1000,"SOLD",Cars!$D$2:$D$1000,B29),"") -> 301.5 | G29: =COUNTIFS(Cars!$B$2:$B$1000,"<>SOLD",Cars!$D$2:$D$1000,B29) -> 1
B30: Alfa Romeo | C30: =COUNTIFS(Cars!$B$2:$B$1000,"SOLD",Cars!$D$2:$D$1000,B30) -> 3 | D30: =SUMIFS(Cars!$X$2:$X$1000,Cars!$B$2:$B$1000,"SOLD",Cars!$D$2:$D$1000,B30) -> 3807 | E30: =IF(C30=0,"",D30/C30) -> 1269 | F30: =IFERROR(AVERAGEIFS(Cars!$Z$2:$Z$1000,Cars!$B$2:$B$1000,"SOLD",Cars!$D$2:$D$1000,B30),"") -> 86.666667 | G30: =COUNTIFS(Cars!$B$2:$B$1000,"<>SOLD",Cars!$D$2:$D$1000,B30) -> 2
B31: BMW | C31: =COUNTIFS(Cars!$B$2:$B$1000,"SOLD",Cars!$D$2:$D$1000,B31) -> 3 | D31: =SUMIFS(Cars!$X$2:$X$1000,Cars!$B$2:$B$1000,"SOLD",Cars!$D$2:$D$1000,B31) -> 2270 | E31: =IF(C31=0,"",D31/C31) -> 756.66667 | F31: =IFERROR(AVERAGEIFS(Cars!$Z$2:$Z$1000,Cars!$B$2:$B$1000,"SOLD",Cars!$D$2:$D$1000,B31),"") -> 58.333333 | G31: =COUNTIFS(Cars!$B$2:$B$1000,"<>SOLD",Cars!$D$2:$D$1000,B31) -> 0
B32: Citroën | C32: =COUNTIFS(Cars!$B$2:$B$1000,"SOLD",Cars!$D$2:$D$1000,B32) -> 3 | D32: =SUMIFS(Cars!$X$2:$X$1000,Cars!$B$2:$B$1000,"SOLD",Cars!$D$2:$D$1000,B32) -> 5930 | E32: =IF(C32=0,"",D32/C32) -> 1976.6667 | F32: =IFERROR(AVERAGEIFS(Cars!$Z$2:$Z$1000,Cars!$B$2:$B$1000,"SOLD",Cars!$D$2:$D$1000,B32),"") -> 93.333333 | G32: =COUNTIFS(Cars!$B$2:$B$1000,"<>SOLD",Cars!$D$2:$D$1000,B32) -> 0
B33: Hyundai | C33: =COUNTIFS(Cars!$B$2:$B$1000,"SOLD",Cars!$D$2:$D$1000,B33) -> 2 | D33: =SUMIFS(Cars!$X$2:$X$1000,Cars!$B$2:$B$1000,"SOLD",Cars!$D$2:$D$1000,B33) -> 2496.21 | E33: =IF(C33=0,"",D33/C33) -> 1248.105 | F33: =IFERROR(AVERAGEIFS(Cars!$Z$2:$Z$1000,Cars!$B$2:$B$1000,"SOLD",Cars!$D$2:$D$1000,B33),"") -> 19 | G33: =COUNTIFS(Cars!$B$2:$B$1000,"<>SOLD",Cars!$D$2:$D$1000,B33) -> 0
B34: Kia | C34: =COUNTIFS(Cars!$B$2:$B$1000,"SOLD",Cars!$D$2:$D$1000,B34) -> 2 | D34: =SUMIFS(Cars!$X$2:$X$1000,Cars!$B$2:$B$1000,"SOLD",Cars!$D$2:$D$1000,B34) -> 2264.71 | E34: =IF(C34=0,"",D34/C34) -> 1132.355 | F34: =IFERROR(AVERAGEIFS(Cars!$Z$2:$Z$1000,Cars!$B$2:$B$1000,"SOLD",Cars!$D$2:$D$1000,B34),"") -> 35 | G34: =COUNTIFS(Cars!$B$2:$B$1000,"<>SOLD",Cars!$D$2:$D$1000,B34) -> 0
B35: Maserati | C35: =COUNTIFS(Cars!$B$2:$B$1000,"SOLD",Cars!$D$2:$D$1000,B35) -> 1 | D35: =SUMIFS(Cars!$X$2:$X$1000,Cars!$B$2:$B$1000,"SOLD",Cars!$D$2:$D$1000,B35) -> 1250 | E35: =IF(C35=0,"",D35/C35) -> 1250 | F35: =IFERROR(AVERAGEIFS(Cars!$Z$2:$Z$1000,Cars!$B$2:$B$1000,"SOLD",Cars!$D$2:$D$1000,B35),"") -> 6 | G35: =COUNTIFS(Cars!$B$2:$B$1000,"<>SOLD",Cars!$D$2:$D$1000,B35) -> 0
... B39: Volvo | C39: =COUNTIFS(Cars!$B$2:$B$1000,"SOLD",Cars!$D$2:$D$1000,B39) -> 2 | D39: =SUMIFS(Cars!$X$2:$X$1000,Cars!$B$2:$B$1000,"SOLD",Cars!$D$2:$D$1000,B39) -> 1954 | E39: =IF(C39=0,"",D39/C39) -> 977 | F39: =IFERROR(AVERAGEIFS(Cars!$Z$2:$Z$1000,Cars!$B$2:$B$1000,"SOLD",Cars!$D$2:$D$1000,B39),"") -> 126 | G39: =COUNTIFS(Cars!$B$2:$B$1000,"<>SOLD",Cars!$D$2:$D$1000,B39) -> 0
B41: Expenses — who paid (to settle between partners)
B42: Paid by | C42: Total (€)
B43: Partner 1 | C43: =SUMIFS(Expenses!$E$2:$E$3000,Expenses!$F$2:$F$3000,B43,Expenses!$B$2:$B$3000,"<>EXAMPLE") -> 0
B44: Partner 2 | C44: =SUMIFS(Expenses!$E$2:$E$3000,Expenses!$F$2:$F$3000,B44,Expenses!$B$2:$B$3000,"<>EXAMPLE") -> 0
B45: Company account | C45: =SUMIFS(Expenses!$E$2:$E$3000,Expenses!$F$2:$F$3000,B45,Expenses!$B$2:$B$3000,"<>EXAMPLE") -> 0

Sheet Cars
A1: Car ID | B1: Status | C1: Deal type | D1: Brand | E1: Model | F1: Trim | G1: First registration | H1: Engine | I1: Gearbox | J1: Drive | K1: Mileage (km) | L1: VIN | M1: Bought in (country) | N1: VAT scheme (M/D) | O1: Purchase date | P1: Purchase price (€) | Q1: Extra costs (€) [from Expenses] | R1: Total cost (€) | S1: Asking price (€) | T1: Sale date | U1: Sale price (€) | V1: VAT & deductions (€) | W1: Commission (€) [consignment only] | X1: Profit (€) | Y1: Margin % of cost | Z1: Days in stock | AA1: Sale month | AB1: Profit per partner (€) [50/50] | AC1: Notes
A2: 1 | B2: SOLD | C2: Own purchase | D2: Hyundai | E2: i40 CW | F2: Business | H2: 1.7 CRDi 104 kW | I2: DCT7 | K2: 159713 | M2: CZ | N2: M | P2: 11103.79 | Q2: =IF(A2="","",SUMIF(Expenses!$B$2:$B$3000,A2,Expenses!$E$2:$E$3000)) -> 0 | R2: =IF(A2="","",N(P2)+N(Q2)) -> 11103.79 | T2: 45034 | U2: 12800 | V2: 0 | X2: =IF(B2<>"SOLD","",IF(C2="Consignment",N(W2)-R2,N(U2)-R2-N(V2))) -> 1696.21 | Y2: =IF(OR(X2="",N(R2)=0),"",X2/R2) -> 0.15275955 | Z2: =IF(O2="","",IF(T2="",TODAY(),T2)-O2) | AA2: =IF(T2="","",TEXT(T2,"YYYY-MM")) -> 2023-04 | AB2: =IF(X2="","",X2/2) -> 848.105
A3: 2 | B3: SOLD | C3: Own purchase | D3: Kia | E3: Cee'd SW | F3: Gold | G3: 43678 | H3: 1.6 CRDi 85 kW | I3: MT6 | K3: 118900 | M3: BE | N3: D | P3: 12942.29 | Q3: =IF(A3="","",SUMIF(Expenses!$B$2:$B$3000,A3,Expenses!$E$2:$E$3000)) -> 0 | R3: =IF(A3="","",N(P3)+N(Q3)) -> 12942.29 | T3: 45115 | U3: 14350 | V3: 0 | X3: =IF(B3<>"SOLD","",IF(C3="Consignment",N(W3)-R3,N(U3)-R3-N(V3))) -> 1407.71 | Y3: =IF(OR(X3="",N(R3)=0),"",X3/R3) -> 0.10876823 | Z3: =IF(O3="","",IF(T3="",TODAY(),T3)-O3) | AA3: =IF(T3="","",TEXT(T3,"YYYY-MM")) -> 2023-07 | AB3: =IF(X3="","",X3/2) -> 703.855
A4: 3 | B4: SOLD | C4: Own purchase | D4: Škoda | E4: Superb Combi | F4: Style | G4: 42461 | H4: 2.0 TDI 110 kW | I4: DSG6 | K4: 194400 | M4: BE | N4: M | P4: 12955.84 | Q4: =IF(A4="","",SUMIF(Expenses!$B$2:$B$3000,A4,Expenses!$E$2:$E$3000)) -> 0 | R4: =IF(A4="","",N(P4)+N(Q4)) -> 12955.84 | T4: 45236 | U4: 15400 | V4: 477.57 | X4: =IF(B4<>"SOLD","",IF(C4="Consignment",N(W4)-R4,N(U4)-R4-N(V4))) -> 1966.59 | Y4: =IF(OR(X4="",N(R4)=0),"",X4/R4) -> 0.15179178 | Z4: =IF(O4="","",IF(T4="",TODAY(),T4)-O4) | AA4: =IF(T4="","",TEXT(T4,"YYYY-MM")) -> 2023-11 | AB4: =IF(X4="","",X4/2) -> 983.295
A5: 4 | B5: SOLD | C5: Own purchase | D5: Mazda | E5: 6 | F5: Revolution | G5: 41395 | H5: 2.5 Skyactiv-G192 | I5: AT6 | K5: 146187 | M5: DE | N5: M | P5: 12873.79 | Q5: =IF(A5="","",SUMIF(Expenses!$B$2:$B$3000,A5,Expenses!$E$2:$E$3000)) -> 0 | R5: =IF(A5="","",N(P5)+N(Q5)) -> 12873.79 | T5: 45120 | U5: 13950 | V5: 0 | X5: =IF(B5<>"SOLD","",IF(C5="Consignment",N(W5)-R5,N(U5)-R5-N(V5))) -> 1076.21 | Y5: =IF(OR(X5="",N(R5)=0),"",X5/R5) -> 0.083596983 | Z5: =IF(O5="","",IF(T5="",TODAY(),T5)-O5) | AA5: =IF(T5="","",TEXT(T5,"YYYY-MM")) -> 2023-07 | AB5: =IF(X5="","",X5/2) -> 538.105
A6: 5 | B6: SOLD | C6: Own purchase | D6: Škoda | E6: Kodiaq | F6: Ambition | G6: 43009 | H6: 1.4 TSI 92 kW | I6: MT6 | K6: 178383 | M6: NL | N6: D | P6: 15569 | Q6: =IF(A6="","",SUMIF(Expenses!$B$2:$B$3000,A6,Expenses!$E$2:$E$3000)) -> 0 | R6: =IF(A6="","",N(P6)+N(Q6)) -> 15569 | T6: 45215 | U6: 17000 | V6: 0 | X6: =IF(B6<>"SOLD","",IF(C6="Consignment",N(W6)-R6,N(U6)-R6-N(V6))) -> 1431 | Y6: =IF(OR(X6="",N(R6)=0),"",X6/R6) -> 0.091913418 | Z6: =IF(O6="","",IF(T6="",TODAY(),T6)-O6) | AA6: =IF(T6="","",TEXT(T6,"YYYY-MM")) -> 2023-10 | AB6: =IF(X6="","",X6/2) -> 715.5
A7: 6 | B7: SOLD | C7: Own purchase | D7: VW | E7: Touran | F7: Highline | G7: 43678 | H7: 2.0 TDI 110 kW | I7: DSG7 | K7: 188761 | M7: DE | N7: D | P7: 14594 | Q7: =IF(A7="","",SUMIF(Expenses!$B$2:$B$3000,A7,Expenses!$E$2:$E$3000)) -> 0 | R7: =IF(A7="","",N(P7)+N(Q7)) -> 14594 | T7: 45209 | U7: 16050 | V7: 0 | X7: =IF(B7<>"SOLD","",IF(C7="Consignment",N(W7)-R7,N(U7)-R7-N(V7))) -> 1456 | Y7: =IF(OR(X7="",N(R7)=0),"",X7/R7) -> 0.099767028 | Z7: =IF(O7="","",IF(T7="",TODAY(),T7)-O7) | AA7: =IF(T7="","",TEXT(T7,"YYYY-MM")) -> 2023-10 | AB7: =IF(X7="","",X7/2) -> 728
A8: 7 | B8: STOCK | C8: Own purchase | D8: Audi | E8: A4 Avant | F8: Basis | G8: 43282 | H8: 2.0 TDI 110 kW | I8: DSG7 | K8: 177534 | M8: IT | N8: D | P8: 12945 | Q8: =IF(A8="","",SUMIF(Expenses!$B$2:$B$3000,A8,Expenses!$E$2:$E$3000)) -> 0 | R8: =IF(A8="","",N(P8)+N(Q8)) -> 12945 | X8: =IF(B8<>"SOLD","",IF(C8="Consignment",N(W8)-R8,N(U8)-R8-N(V8))) | Y8: =IF(OR(X8="",N(R8)=0),"",X8/R8) | Z8: =IF(O8="","",IF(T8="",TODAY(),T8)-O8) | AA8: =IF(T8="","",TEXT(T8,"YYYY-MM")) | AB8: =IF(X8="","",X8/2)
A9: 8 | B9: SOLD | C9: Own purchase | D9: Škoda | E9: Octavia Combi | F9: Ambition | G9: 43160 | H9: 1.0 TSI 85 kW | I9: DSG7 | K9: 188436 | M9: NL | N9: D | P9: 10029.6 | Q9: =IF(A9="","",SUMIF(Expenses!$B$2:$B$3000,A9,Expenses!$E$2:$E$3000)) -> 0 | R9: =IF(A9="","",N(P9)+N(Q9)) -> 10029.6 | T9: 45238 | U9: 11000 | V9: 0 | X9: =IF(B9<>"SOLD","",IF(C9="Consignment",N(W9)-R9,N(U9)-R9-N(V9))) -> 970.4 | Y9: =IF(OR(X9="",N(R9)=0),"",X9/R9) -> 0.096753609 | Z9: =IF(O9="","",IF(T9="",TODAY(),T9)-O9) | AA9: =IF(T9="","",TEXT(T9,"YYYY-MM")) -> 2023-11 | AB9: =IF(X9="","",X9/2) -> 485.2
A10: 9 | B10: SOLD | C10: Own purchase | D10: VW | E10: Passat | F10: Comfortline | G10: 42767 | H10: 2.0 TDI 110 kW | I10: DSG6 | K10: 185900 | M10: SK | N10: D | P10: 13622 | Q10: =IF(A10="","",SUMIF(Expenses!$B$2:$B$3000,A10,Expenses!$E$2:$E$3000)) -> 0 | R10: =IF(A10="","",N(P10)+N(Q10)) -> 13622 | T10: 45289 | U10: 14850 | V10: 0 | X10: =IF(B10<>"SOLD","",IF(C10="Consignment",N(W10)-R10,N(U10)-R10-N(V10))) -> 1228 | Y10: =IF(OR(X10="",N(R10)=0),"",X10/R10) -> 0.09014829 | Z10: =IF(O10="","",IF(T10="",TODAY(),T10)-O10) | AA10: =IF(T10="","",TEXT(T10,"YYYY-MM")) -> 2023-12 | AB10: =IF(X10="","",X10/2) -> 614
A11: 10 | B11: SOLD | C11: Own purchase | D11: VW | E11: Passat Variant R-line | F11: Highline Business | G11: 42248 | H11: 1.8 TSI 132 kW | I11: DSG7 | K11: 187200 | M11: NL | N11: D | O11: 45232 | P11: 12362.56 | Q11: =IF(A11="","",SUMIF(Expenses!$B$2:$B$3000,A11,Expenses!$E$2:$E$3000)) -> 0 | R11: =IF(A11="","",N(P11)+N(Q11)) -> 12362.56 | T11: 45449 | U11: 12900 | V11: 2066.44 | X11: =IF(B11<>"SOLD","",IF(C11="Consignment",N(W11)-R11,N(U11)-R11-N(V11))) -> -1529 | Y11: =IF(OR(X11="",N(R11)=0),"",X11/R11) -> -0.12367989 | Z11: =IF(O11="","",IF(T11="",TODAY(),T11)-O11) -> 217 | AA11: =IF(T11="","",TEXT(T11,"YYYY-MM")) -> 2024-06 | AB11: =IF(X11="","",X11/2) -> -764.5
A12: 11 | B12: SOLD | C12: Own purchase | D12: VW | E12: Touran R-line | F12: Highline | G12: 43101 | H12: 1.8 TSI 132 kW | I12: DSG7 | K12: 151400 | M12: NL | N12: M | O12: 45236 | P12: 17778.05 | Q12: =IF(A12="","",SUMIF(Expenses!$B$2:$B$3000,A12,Expenses!$E$2:$E$3000)) -> 0 | R12: =IF(A12="","",N(P12)+N(Q12)) -> 17778.05 | T12: 45400 | U12: 18390 | V12: -0.05 | X12: =IF(B12<>"SOLD","",IF(C12="Consignment",N(W12)-R12,N(U12)-R12-N(V12))) -> 612 | Y12: =IF(OR(X12="",N(R12)=0),"",X12/R12) -> 0.034424473 | Z12: =IF(O12="","",IF(T12="",TODAY(),T12)-O12) -> 164 | AA12: =IF(T12="","",TEXT(T12,"YYYY-MM")) -> 2024-04 | AB12: =IF(X12="","",X12/2) -> 306
A13: 12 | B13: SOLD | C13: Own purchase | D13: Škoda | E13: Kodiaq | F13: Style | G13: 42887 | H13: 1.4 TSI 110 kW | I13: DSG6 | K13: 154100 | M13: FR | N13: M | O13: 45233 | P13: 18000.19 | Q13: =IF(A13="","",SUMIF(Expenses!$B$2:$B$3000,A13,Expenses!$E$2:$E$3000)) -> 0 | R13: =IF(A13="","",N(P13)+N(Q13)) -> 18000.19 | T13: 45380 | U13: 20500 | V13: -0.19 | X13: =IF(B13<>"SOLD","",IF(C13="Consignment",N(W13)-R13,N(U13)-R13-N(V13))) -> 2500 | Y13: =IF(OR(X13="",N(R13)=0),"",X13/R13) -> 0.13888742 | Z13: =IF(O13="","",IF(T13="",TODAY(),T13)-O13) -> 147 | AA13: =IF(T13="","",TEXT(T13,"YYYY-MM")) -> 2024-03 | AB13: =IF(X13="","",X13/2) -> 1250
A14: 13 | B14: SOLD | C14: Own purchase | D14: Seat | E14: Ateca | F14: Style | G14: 43862 | H14: 1.0 TSI 85 kW | I14: MT6 | K14: 176499 | M14: NL | N14: D | O14: 45243 | P14: 13424 | Q14: =IF(A14="","",SUMIF(Expenses!$B$2:$B$3000,A14,Expenses!$E$2:$E$3000)) -> 0 | R14: =IF(A14="","",N(P14)+N(Q14)) -> 13424 | T14: 45386 | U14: 13990 | V14: -10 | X14: =IF(B14<>"SOLD","",IF(C14="Consignment",N(W14)-R14,N(U14)-R14-N(V14))) -> 576 | Y14: =IF(OR(X14="",N(R14)=0),"",X14/R14) -> 0.042908224 | Z14: =IF(O14="","",IF(T14="",TODAY(),T14)-O14) -> 143 | AA14: =IF(T14="","",TEXT(T14,"YYYY-MM")) -> 2024-04 | AB14: =IF(X14="","",X14/2) -> 288
A15: 15 | B15: SOLD | C15: Own purchase | D15: Seat | E15: Arona | F15: Style | G15: 43497 | H15: 1.6 TDI 70 kW | I15: MT6 | K15: 67396 | M15: BE | N15: M | O15: 45251 | P15: 12564.68 | Q15: =IF(A15="","",SUMIF(Expenses!$B$2:$B$3000,A15,Expenses!$E$2:$E$3000)) -> 0 | R15: =IF(A15="","",N(P15)+N(Q15)) -> 12564.68 | T15: 45339 | U15: 14500 | V15: 0.32 | X15: =IF(B15<>"SOLD","",IF(C15="Consignment",N(W15)-R15,N(U15)-R15-N(V15))) -> 1935 | Y15: =IF(OR(X15="",N(R15)=0),"",X15/R15) -> 0.15400313 | Z15: =IF(O15="","",IF(T15="",TODAY(),T15)-O15) -> 88 | AA15: =IF(T15="","",TEXT(T15,"YYYY-MM")) -> 2024-02 | AB15: =IF(X15="","",X15/2) -> 967.5
A16: 16 | B16: SOLD | C16: Own purchase | D16: Audi | E16: A4 Avant | F16: Basis | G16: 42370 | H16: 2.0 TDI 110 kW | I16: DSG7 | K16: 211000 | M16: DK | N16: D | O16: 45352 | P16: 9898.67 | Q16: =IF(A16="","",SUMIF(Expenses!$B$2:$B$3000,A16,Expenses!$E$2:$E$3000)) -> 0 | R16: =IF(A16="","",N(P16)+N(Q16)) -> 9898.67 | T16: 45384 | U16: 14000 | V16: 2333.33 | X16: =IF(B16<>"SOLD","",IF(C16="Consignment",N(W16)-R16,N(U16)-R16-N(V16))) -> 1768 | Y16: =IF(OR(X16="",N(R16)=0),"",X16/R16) -> 0.17860985 | Z16: =IF(O16="","",IF(T16="",TODAY(),T16)-O16) -> 32 | AA16: =IF(T16="","",TEXT(T16,"YYYY-MM")) -> 2024-04 | AB16: =IF(X16="","",X16/2) -> 884
A17: 17 | B17: SOLD | C17: Own purchase | D17: Volvo | E17: V60 | F17: Cross Country | G17: 43009 | H17: 2.0 D4 140 kW | I17: AT8 | K17: 196000 | M17: DE | N17: M | O17: 45380 | P17: 13305 | Q17: =IF(A17="","",SUMIF(Expenses!$B$2:$B$3000,A17,Expenses!$E$2:$E$3000)) -> 0 | R17: =IF(A17="","",N(P17)+N(Q17)) -> 13305 | T17: 45418 | U17: 13900 | V17: 0 | X17: =IF(B17<>"SOLD","",IF(C17="Consignment",N(W17)-R17,N(U17)-R17-N(V17))) -> 595 | Y17: =IF(OR(X17="",N(R17)=0),"",X17/R17) -> 0.04472003 | Z17: =IF(O17="","",IF(T17="",TODAY(),T17)-O17) -> 38 | AA17: =IF(T17="","",TEXT(T17,"YYYY-MM")) -> 2024-05 | AB17: =IF(X17="","",X17/2) -> 297.5
A18: 18 | B18: SOLD | C18: Own purchase | D18: Mercedes-Benz | E18: C 220d T-Modell | F18: Business Plus | G18: 43009 | H18: 2.2d 125 kW | I18: AT9 | K18: 212000 | M18: DK | N18: D | O18: 45394 | P18: 11629 | Q18: =IF(A18="","",SUMIF(Expenses!$B$2:$B$3000,A18,Expenses!$E$2:$E$3000)) -> 0 | R18: =IF(A18="","",N(P18)+N(Q18)) -> 11629 | T18: 45537 | U18: 14900 | V18: 2483 | X18: =IF(B18<>"SOLD","",IF(C18="Consignment",N(W18)-R18,N(U18)-R18-N(V18))) -> 788 | Y18: =IF(OR(X18="",N(R18)=0),"",X18/R18) -> 0.06776163 | Z18: =IF(O18="","",IF(T18="",TODAY(),T18)-O18) -> 143 | AA18: =IF(T18="","",TEXT(T18,"YYYY-MM")) -> 2024-09 | AB18: =IF(X18="","",X18/2) -> 394
A19: 19 | B19: SOLD | C19: Own purchase | D19: Škoda | E19: Octavia Combi | F19: Style | G19: 43405 | H19: 1.0 TSI 85 kW | I19: MT6 | K19: 201000 | M19: NL | N19: D | O19: 45412 | P19: 8067 | Q19: =IF(A19="","",SUMIF(Expenses!$B$2:$B$3000,A19,Expenses!$E$2:$E$3000)) -> 0 | R19: =IF(A19="","",N(P19)+N(Q19)) -> 8067 | T19: 45451 | U19: 10500 | V19: 0 | X19: =IF(B19<>"SOLD","",IF(C19="Consignment",N(W19)-R19,N(U19)-R19-N(V19))) -> 2433 | Y19: =IF(OR(X19="",N(R19)=0),"",X19/R19) -> 0.30159911 | Z19: =IF(O19="","",IF(T19="",TODAY(),T19)-O19) -> 39 | AA19: =IF(T19="","",TEXT(T19,"YYYY-MM")) -> 2024-06 | AB19: =IF(X19="","",X19/2) -> 1216.5
A20: 20 | B20: SOLD | C20: Own purchase | D20: Škoda | E20: Octavia Combi | F20: Style | G20: 43891 | H20: 2.0 TDI 110 kW | I20: DSG7 | K20: 193000 | M20: DK | N20: D | O20: 45415 | P20: 10345 | Q20: =IF(A20="","",SUMIF(Expenses!$B$2:$B$3000,A20,Expenses!$E$2:$E$3000)) -> 0 | R20: =IF(A20="","",N(P20)+N(Q20)) -> 10345 | T20: 45471 | U20: 14490 | V20: 2415 | X20: =IF(B20<>"SOLD","",IF(C20="Consignment",N(W20)-R20,N(U20)-R20-N(V20))) -> 1730 | Y20: =IF(OR(X20="",N(R20)=0),"",X20/R20) -> 0.16723055 | Z20: =IF(O20="","",IF(T20="",TODAY(),T20)-O20) -> 56 | AA20: =IF(T20="","",TEXT(T20,"YYYY-MM")) -> 2024-06 | AB20: =IF(X20="","",X20/2) -> 865
A21: 21 | B21: SOLD | C21: Own purchase | D21: Audi | E21: A4 Avant | F21: S-line | G21: 42430 | H21: 2.0 TDI 140 kW | I21: DSG7 | K21: 160000 | M21: DK | N21: D | O21: 45422 | P21: 12529 | Q21: =IF(A21="","",SUMIF(Expenses!$B$2:$B$3000,A21,Expenses!$E$2:$E$3000)) -> 0 | R21: =IF(A21="","",N(P21)+N(Q21)) -> 12529 | T21: 45443 | U21: 18700 | V21: 3117 | X21: =IF(B21<>"SOLD","",IF(C21="Consignment",N(W21)-R21,N(U21)-R21-N(V21))) -> 3054 | Y21: =IF(OR(X21="",N(R21)=0),"",X21/R21) -> 0.24375449 | Z21: =IF(O21="","",IF(T21="",TODAY(),T21)-O21) -> 21 | AA21: =IF(T21="","",TEXT(T21,"YYYY-MM")) -> 2024-05 | AB21: =IF(X21="","",X21/2) -> 1527
A22: 22 | B22: SOLD | C22: Own purchase | D22: Audi | E22: Q5 quattro | F22: Basis | G22: 40787 | H22: 3.0 TDI 176 kW 4x4 | I22: DSG7 | J22: 4x4 | K22: 182000 | M22: IT | N22: D | O22: 45444 | P22: 9024 | Q22: =IF(A22="","",SUMIF(Expenses!$B$2:$B$3000,A22,Expenses!$E$2:$E$3000)) -> 0 | R22: =IF(A22="","",N(P22)+N(Q22)) -> 9024 | T22: 45508 | U22: 13100 | V22: 2183 | X22: =IF(B22<>"SOLD","",IF(C22="Consignment",N(W22)-R22,N(U22)-R22-N(V22))) -> 1893 | Y22: =IF(OR(X22="",N(R22)=0),"",X22/R22) -> 0.20977394 | Z22: =IF(O22="","",IF(T22="",TODAY(),T22)-O22) -> 64 | AA22: =IF(T22="","",TEXT(T22,"YYYY-MM")) -> 2024-08 | AB22: =IF(X22="","",X22/2) -> 946.5
A23: 23 | B23: SOLD | C23: Own purchase | D23: Mazda | E23: 6 | F23: Revolution | G23: 43009 | H23: 2.5i 141 kW | I23: AT6 | K23: 159000 | M23: DK | N23: M | O23: 45429 | P23: 14215 | Q23: =IF(A23="","",SUMIF(Expenses!$B$2:$B$3000,A23,Expenses!$E$2:$E$3000)) -> 0 | R23: =IF(A23="","",N(P23)+N(Q23)) -> 14215 | T23: 45519 | U23: 16300 | V23: 0 | X23: =IF(B23<>"SOLD","",IF(C23="Consignment",N(W23)-R23,N(U23)-R23-N(V23))) -> 2085 | Y23: =IF(OR(X23="",N(R23)=0),"",X23/R23) -> 0.14667605 | Z23: =IF(O23="","",IF(T23="",TODAY(),T23)-O23) -> 90 | AA23: =IF(T23="","",TEXT(T23,"YYYY-MM")) -> 2024-08 | AB23: =IF(X23="","",X23/2) -> 1042.5
A24: 24 | B24: SOLD | C24: Own purchase | D24: Škoda | E24: Octavia Combi | F24: Style | G24: 43891 | H24: 2.0 TDI 110 kW | I24: DSG7 | K24: 259000 | M24: DK | N24: D | O24: 45429 | P24: 8387 | Q24: =IF(A24="","",SUMIF(Expenses!$B$2:$B$3000,A24,Expenses!$E$2:$E$3000)) -> 0 | R24: =IF(A24="","",N(P24)+N(Q24)) -> 8387 | T24: 45470 | U24: 10750 | V24: 1792 | X24: =IF(B24<>"SOLD","",IF(C24="Consignment",N(W24)-R24,N(U24)-R24-N(V24))) -> 571 | Y24: =IF(OR(X24="",N(R24)=0),"",X24/R24) -> 0.068081555 | Z24: =IF(O24="","",IF(T24="",TODAY(),T24)-O24) -> 41 | AA24: =IF(T24="","",TEXT(T24,"YYYY-MM")) -> 2024-06 | AB24: =IF(X24="","",X24/2) -> 285.5
A25: 25 | B25: SOLD | C25: Own purchase | D25: Škoda | E25: Octavia Combi | F25: Style | G25: 42887 | H25: 1.0 TSI 85 kW | I25: DSG7 | K25: 188000 | M25: DE | N25: M | O25: 45453 | P25: 8221 | Q25: =IF(A25="","",SUMIF(Expenses!$B$2:$B$3000,A25,Expenses!$E$2:$E$3000)) -> 0 | R25: =IF(A25="","",N(P25)+N(Q25)) -> 8221 | T25: 45526 | U25: 10000 | V25: 0 | X25: =IF(B25<>"SOLD","",IF(C25="Consignment",N(W25)-R25,N(U25)-R25-N(V25))) -> 1779 | Y25: =IF(OR(X25="",N(R25)=0),"",X25/R25) -> 0.21639703 | Z25: =IF(O25="","",IF(T25="",TODAY(),T25)-O25) -> 73 | AA25: =IF(T25="","",TEXT(T25,"YYYY-MM")) -> 2024-08 | AB25: =IF(X25="","",X25/2) -> 889.5
A26: 26 | B26: SOLD | C26: Own purchase | D26: VW | E26: Passat Variant | F26: Highline | G26: 43800 | H26: 1.5 TSI 110 kW | I26: MT6 | K26: 144000 | M26: DE | N26: D | O26: 45456 | P26: 18813.42 | Q26: =IF(A26="","",SUMIF(Expenses!$B$2:$B$3000,A26,Expenses!$E$2:$E$3000)) -> 0 | R26: =IF(A26="","",N(P26)+N(Q26)) -> 18813.42 | T26: 45476 | U26: 20800 | V26: -0.42 | X26: =IF(B26<>"SOLD","",IF(C26="Consignment",N(W26)-R26,N(U26)-R26-N(V26))) -> 1987 | Y26: =IF(OR(X26="",N(R26)=0),"",X26/R26) -> 0.1056161 | Z26: =IF(O26="","",IF(T26="",TODAY(),T26)-O26) -> 20 | AA26: =IF(T26="","",TEXT(T26,"YYYY-MM")) -> 2024-07 | AB26: =IF(X26="","",X26/2) -> 993.5
A27: 27 | B27: SOLD | C27: Own purchase | D27: Škoda | E27: Superb Combi | F27: Style | G27: 43374 | H27: 2.0 TDI 110 kW | I27: MT6 | K27: 186000 | M27: BE | N27: D | O27: 45457 | P27: 9880.5 | Q27: =IF(A27="","",SUMIF(Expenses!$B$2:$B$3000,A27,Expenses!$E$2:$E$3000)) -> 0 | R27: =IF(A27="","",N(P27)+N(Q27)) -> 9880.5 | T27: 45527 | U27: 16200 | V27: 2249.5 | X27: =IF(B27<>"SOLD","",IF(C27="Consignment",N(W27)-R27,N(U27)-R27-N(V27))) -> 4070 | Y27: =IF(OR(X27="",N(R27)=0),"",X27/R27) -> 0.41192247 | Z27: =IF(O27="","",IF(T27="",TODAY(),T27)-O27) -> 70 | AA27: =IF(T27="","",TEXT(T27,"YYYY-MM")) -> 2024-08 | AB27: =IF(X27="","",X27/2) -> 2035
A28: 28 | B28: SOLD | C28: Own purchase | D28: Seat | E28: Arona | F28: Style | G28: 43282 | H28: 1.6 TDI 70 kW | I28: MT5 | K28: 155000 | M28: FR | N28: M | O28: 45462 | P28: 10145 | Q28: =IF(A28="","",SUMIF(Expenses!$B$2:$B$3000,A28,Expenses!$E$2:$E$3000)) -> 0 | R28: =IF(A28="","",N(P28)+N(Q28)) -> 10145 | T28: 45514 | U28: 12700 | V28: 0 | X28: =IF(B28<>"SOLD","",IF(C28="Consignment",N(W28)-R28,N(U28)-R28-N(V28))) -> 2555 | Y28: =IF(OR(X28="",N(R28)=0),"",X28/R28) -> 0.2518482 | Z28: =IF(O28="","",IF(T28="",TODAY(),T28)-O28) -> 52 | AA28: =IF(T28="","",TEXT(T28,"YYYY-MM")) -> 2024-08 | AB28: =IF(X28="","",X28/2) -> 1277.5
A29: 29 | B29: SOLD | C29: Own purchase | D29: Audi | E29: A4 Avant | F29: Basis | G29: 42401 | H29: 2.0 TDI 110 kW | I29: DSG7 | K29: 163000 | M29: IT | N29: M | O29: 45467 | P29: 12482.5 | Q29: =IF(A29="","",SUMIF(Expenses!$B$2:$B$3000,A29,Expenses!$E$2:$E$3000)) -> 0 | R29: =IF(A29="","",N(P29)+N(Q29)) -> 12482.5 | T29: 45523 | U29: 16000 | V29: -0.5 | X29: =IF(B29<>"SOLD","",IF(C29="Consignment",N(W29)-R29,N(U29)-R29-N(V29))) -> 3518 | Y29: =IF(OR(X29="",N(R29)=0),"",X29/R29) -> 0.28183457 | Z29: =IF(O29="","",IF(T29="",TODAY(),T29)-O29) -> 56 | AA29: =IF(T29="","",TEXT(T29,"YYYY-MM")) -> 2024-08 | AB29: =IF(X29="","",X29/2) -> 1759
A30: 30 | B30: SOLD | C30: Own purchase | D30: Škoda | E30: Octavia Combi | F30: Ambition | G30: 43132 | H30: 1.0 TSI 85 kW | I30: MT6 | K30: 166700 | M30: BE | N30: D | O30: 45476 | P30: 8750.67 | Q30: =IF(A30="","",SUMIF(Expenses!$B$2:$B$3000,A30,Expenses!$E$2:$E$3000)) -> 0 | R30: =IF(A30="","",N(P30)+N(Q30)) -> 8750.67 | T30: 45605 | U30: 9700 | V30: 199.33 | X30: =IF(B30<>"SOLD","",IF(C30="Consignment",N(W30)-R30,N(U30)-R30-N(V30))) -> 750 | Y30: =IF(OR(X30="",N(R30)=0),"",X30/R30) -> 0.085707723 | Z30: =IF(O30="","",IF(T30="",TODAY(),T30)-O30) -> 129 | AA30: =IF(T30="","",TEXT(T30,"YYYY-MM")) -> 2024-11 | AB30: =IF(X30="","",X30/2) -> 375
A31: 31 | B31: SOLD | C31: Own purchase | D31: Alfa Romeo | E31: Stelvio | F31: Executive | G31: 43040 | H31: 2.2d 154 kW | I31: AT8 | J31: 4x4 | K31: 157200 | M31: IT | N31: D | O31: 45484 | P31: 14740 | Q31: =IF(A31="","",SUMIF(Expenses!$B$2:$B$3000,A31,Expenses!$E$2:$E$3000)) -> 0 | R31: =IF(A31="","",N(P31)+N(Q31)) -> 14740 | T31: 45706 | U31: 20750 | V31: 3880 | X31: =IF(B31<>"SOLD","",IF(C31="Consignment",N(W31)-R31,N(U31)-R31-N(V31))) -> 2130 | Y31: =IF(OR(X31="",N(R31)=0),"",X31/R31) -> 0.14450475 | Z31: =IF(O31="","",IF(T31="",TODAY(),T31)-O31) -> 222 | AA31: =IF(T31="","",TEXT(T31,"YYYY-MM")) -> 2025-02 | AB31: =IF(X31="","",X31/2) -> 1065
A32: 32 | B32: SOLD | C32: Own purchase | D32: Audi | E32: A4 Avant | F32: Basis | G32: 42522 | H32: 2.0 TDI 110 kW | I32: DSG7 | K32: 174500 | M32: DE | N32: M | O32: 45483 | P32: 13121.67 | Q32: =IF(A32="","",SUMIF(Expenses!$B$2:$B$3000,A32,Expenses!$E$2:$E$3000)) -> 0 | R32: =IF(A32="","",N(P32)+N(Q32)) -> 13121.67 | T32: 45527 | U32: 15700 | V32: 0.33 | X32: =IF(B32<>"SOLD","",IF(C32="Consignment",N(W32)-R32,N(U32)-R32-N(V32))) -> 2578 | Y32: =IF(OR(X32="",N(R32)=0),"",X32/R32) -> 0.19646889 | Z32: =IF(O32="","",IF(T32="",TODAY(),T32)-O32) -> 44 | AA32: =IF(T32="","",TEXT(T32,"YYYY-MM")) -> 2024-08 | AB32: =IF(X32="","",X32/2) -> 1289
A33: 33 | B33: SOLD | C33: Own purchase | D33: VW | E33: Touareg | F33: Exclusive | G33: 39630 | H33: 3.0 TDI 176 kW | I33: AT6 | J33: 4x4 | K33: 208900 | M33: IT | N33: M | O33: 45514 | P33: 7780.83 | Q33: =IF(A33="","",SUMIF(Expenses!$B$2:$B$3000,A33,Expenses!$E$2:$E$3000)) -> 0 | R33: =IF(A33="","",N(P33)+N(Q33)) -> 7780.83 | T33: 45580 | U33: 9300 | V33: 0.17 | X33: =IF(B33<>"SOLD","",IF(C33="Consignment",N(W33)-R33,N(U33)-R33-N(V33))) -> 1519 | Y33: =IF(OR(X33="",N(R33)=0),"",X33/R33) -> 0.19522339 | Z33: =IF(O33="","",IF(T33="",TODAY(),T33)-O33) -> 66 | AA33: =IF(T33="","",TEXT(T33,"YYYY-MM")) -> 2024-10 | AB33: =IF(X33="","",X33/2) -> 759.5
A34: 34 | B34: SOLD | C34: Own purchase | D34: VW | E34: Golf Variant | F34: Comfortline | G34: 42948 | H34: 2.0 TDI 110 kW | I34: MT6 | K34: 139300 | M34: BE | N34: D | O34: 45517 | P34: 9470 | Q34: =IF(A34="","",SUMIF(Expenses!$B$2:$B$3000,A34,Expenses!$E$2:$E$3000)) -> 0 | R34: =IF(A34="","",N(P34)+N(Q34)) -> 9470 | T34: 45596 | U34: 14100 | V34: 2350 | X34: =IF(B34<>"SOLD","",IF(C34="Consignment",N(W34)-R34,N(U34)-R34-N(V34))) -> 2280 | Y34: =IF(OR(X34="",N(R34)=0),"",X34/R34) -> 0.2407603 | Z34: =IF(O34="","",IF(T34="",TODAY(),T34)-O34) -> 79 | AA34: =IF(T34="","",TEXT(T34,"YYYY-MM")) -> 2024-10 | AB34: =IF(X34="","",X34/2) -> 1140
A35: 35 | B35: SOLD | C35: Own purchase | D35: Škoda | E35: Superb Combi | F35: Style | G35: 42736 | H35: 1.4 TSI 110 kW | I35: MT6 | K35: 148700 | M35: AT | N35: M | O35: 45518 | P35: 13751 | Q35: =IF(A35="","",SUMIF(Expenses!$B$2:$B$3000,A35,Expenses!$E$2:$E$3000)) -> 0 | R35: =IF(A35="","",N(P35)+N(Q35)) -> 13751 | T35: 45532 | U35: 15300 | V35: 0 | X35: =IF(B35<>"SOLD","",IF(C35="Consignment",N(W35)-R35,N(U35)-R35-N(V35))) -> 1549 | Y35: =IF(OR(X35="",N(R35)=0),"",X35/R35) -> 0.11264635 | Z35: =IF(O35="","",IF(T35="",TODAY(),T35)-O35) -> 14 | AA35: =IF(T35="","",TEXT(T35,"YYYY-MM")) -> 2024-08 | AB35: =IF(X35="","",X35/2) -> 774.5
A36: 36 | B36: SOLD | C36: Own purchase | D36: VW | E36: Passat Variant | F36: Comfortline | G36: 42248 | H36: 2.0 TDI 110 kW | I36: DSG7 | K36: 195700 | M36: DE | N36: M | O36: 45530 | P36: 11606.67 | Q36: =IF(A36="","",SUMIF(Expenses!$B$2:$B$3000,A36,Expenses!$E$2:$E$3000)) -> 0 | R36: =IF(A36="","",N(P36)+N(Q36)) -> 11606.67 | T36: 45593 | U36: 13850 | V36: 0.33 | X36: =IF(B36<>"SOLD","",IF(C36="Consignment",N(W36)-R36,N(U36)-R36-N(V36))) -> 2243 | Y36: =IF(OR(X36="",N(R36)=0),"",X36/R36) -> 0.19325095 | Z36: =IF(O36="","",IF(T36="",TODAY(),T36)-O36) -> 63 | AA36: =IF(T36="","",TEXT(T36,"YYYY-MM")) -> 2024-10 | AB36: =IF(X36="","",X36/2) -> 1121.5
A37: 37 | B37: SOLD | C37: Own purchase | D37: Škoda | E37: Octavia Combi | F37: Ambition | G37: 43221 | H37: 1.6 TDI 85 kW | I37: MT5 | K37: 176100 | M37: DE | N37: D | O37: 45532 | P37: 7566 | Q37: =IF(A37="","",SUMIF(Expenses!$B$2:$B$3000,A37,Expenses!$E$2:$E$3000)) -> 0 | R37: =IF(A37="","",N(P37)+N(Q37)) -> 7566 | T37: 45639 | U37: 9980 | V37: 1450 | X37: =IF(B37<>"SOLD","",IF(C37="Consignment",N(W37)-R37,N(U37)-R37-N(V37))) -> 964 | Y37: =IF(OR(X37="",N(R37)=0),"",X37/R37) -> 0.12741211 | Z37: =IF(O37="","",IF(T37="",TODAY(),T37)-O37) -> 107 | AA37: =IF(T37="","",TEXT(T37,"YYYY-MM")) -> 2024-12 | AB37: =IF(X37="","",X37/2) -> 482
A38: 38 | B38: SOLD | C38: Own purchase | D38: Škoda | E38: Octavia Combi | F38: Ambition | G38: 43040 | H38: 1.6 TDI 85 kW | I38: MT6 | K38: 113100 | M38: IT | N38: M | O38: 45534 | P38: 9985 | Q38: =IF(A38="","",SUMIF(Expenses!$B$2:$B$3000,A38,Expenses!$E$2:$E$3000)) -> 0 | R38: =IF(A38="","",N(P38)+N(Q38)) -> 9985 | T38: 45615 | U38: 12000 | V38: 0 | X38: =IF(B38<>"SOLD","",IF(C38="Consignment",N(W38)-R38,N(U38)-R38-N(V38))) -> 2015 | Y38: =IF(OR(X38="",N(R38)=0),"",X38/R38) -> 0.2018027 | Z38: =IF(O38="","",IF(T38="",TODAY(),T38)-O38) -> 81 | AA38: =IF(T38="","",TEXT(T38,"YYYY-MM")) -> 2024-11 | AB38: =IF(X38="","",X38/2) -> 1007.5
A39: 39 | B39: SOLD | C39: Own purchase | D39: Seat | E39: Leon ST | F39: Stylance | G39: 43709 | H39: 2.0 TDI 110 kW | I39: MT6 | K39: 197800 | M39: LU | N39: D | O39: 45537 | P39: 7180 | Q39: =IF(A39="","",SUMIF(Expenses!$B$2:$B$3000,A39,Expenses!$E$2:$E$3000)) -> 0 | R39: =IF(A39="","",N(P39)+N(Q39)) -> 7180 | T39: 45640 | U39: 10500 | V39: 1750 | X39: =IF(B39<>"SOLD","",IF(C39="Consignment",N(W39)-R39,N(U39)-R39-N(V39))) -> 1570 | Y39: =IF(OR(X39="",N(R39)=0),"",X39/R39) -> 0.21866295 | Z39: =IF(O39="","",IF(T39="",TODAY(),T39)-O39) -> 103 | AA39: =IF(T39="","",TEXT(T39,"YYYY-MM")) -> 2024-12 | AB39: =IF(X39="","",X39/2) -> 785
A40: 40 | B40: SOLD | C40: Own purchase | D40: Audi | E40: A4 Avant | F40: Basis | G40: 42401 | H40: 2.0 TDI 110 kW | I40: DSG7 | K40: 175900 | M40: IT | N40: M | O40: 45537 | P40: 12454.17 | Q40: =IF(A40="","",SUMIF(Expenses!$B$2:$B$3000,A40,Expenses!$E$2:$E$3000)) -> 0 | R40: =IF(A40="","",N(P40)+N(Q40)) -> 12454.17 | T40: 45640 | U40: 14000 | V40: -0.17 | X40: =IF(B40<>"SOLD","",IF(C40="Consignment",N(W40)-R40,N(U40)-R40-N(V40))) -> 1546 | Y40: =IF(OR(X40="",N(R40)=0),"",X40/R40) -> 0.12413513 | Z40: =IF(O40="","",IF(T40="",TODAY(),T40)-O40) -> 103 | AA40: =IF(T40="","",TEXT(T40,"YYYY-MM")) -> 2024-12 | AB40: =IF(X40="","",X40/2) -> 773
...

Sheet Expenses
A1: Date | B1: Car ID | C1: Category | D1: Description | E1: Amount (€) | F1: Paid by | G1: Invoice / receipt no.
A2: 46223 | B2: EXAMPLE | C2: Repair & service | D2: Example row — serpentine belt + oil change (delete me) | E2: 240 | F2: Partner 1 | G2: FA-2026-0123

Sheet Lists
A1: Status | B1: Deal type | C1: Brand | D1: Gearbox | E1: Drive | F1: Country | G1: VAT scheme | H1: Expense category | I1: Paid by
A2: STOCK | B2: Own purchase | C2: Alfa Romeo | D2: MT5 | E2: FWD | F2: SK | G2: M | H2: Transport / import | I2: Partner 1
A3: RESERVED | B3: Consignment | C3: Audi | D3: MT6 | E3: RWD | F3: CZ | G3: D | H3: Repair & service | I3: Partner 2
A4: SOLD | C4: BMW | D4: DSG6 | E4: 4x4 | F4: AT | H4: Tyres | I4: Company account
C5: Citroën | D5: DSG7 | F5: DE | H5: Cleaning & detailing
C6: Cupra | D6: DCT7 | F6: NL | H6: STK / EK
C7: Ford | D7: DCT8 | F7: BE | H7: Registration & fees
C8: Hyundai | D8: AT1 | F8: LU | H8: Advertising
C9: Kia | D9: AT6 | F9: DK | H9: Fuel
C10: Maserati | D10: AT7 | F10: SE | H10: Other
C11: Mazda | D11: AT8 | F11: FR
C12: Mercedes-Benz | D12: AT9 | F12: IT
C13: Nissan | D13: EDC6 | F13: ES
C14: Opel | F14: HU
C15: Renault | F15: PL
C16: Seat
C17: Toyota
C18: VW
C19: Volvo
C20: Škoda
A62: Add new values at the bottom of a column — the dropdowns pick them up automatically (up to row 60). Rename "Partner 1 / Partner 2" to your names.

Sheet Check these
A1: Things found while moving your data — please check and fix on the Cars tab, then delete the line here
A3: Car ID | B3: Car | C3: What looks wrong | D3: What I did
A4: 1 | B4: Hyundai i40 CW (?) | C4: Purchase date missing. | D4: Left empty — "Days in stock" cannot be calculated. Please fill in.
A5: 1 | B5: Hyundai i40 CW (?) | C5: First registration (model year) missing. | D5: Left empty. Please fill in from the registration papers.
A6: 2 | B6: Kia Cee'd SW (08/2019) | C6: Purchase date missing. | D6: Left empty — "Days in stock" cannot be calculated. Please fill in.
A7: 3 | B7: Škoda Superb Combi (04/2016) | C7: Purchase date missing. | D7: Left empty — "Days in stock" cannot be calculated. Please fill in.
A8: 4 | B8: Mazda 6 (05/2013) | C8: Purchase date missing. | D8: Left empty — "Days in stock" cannot be calculated. Please fill in.
A9: 5 | B9: Škoda Kodiaq (10/2017) | C9: Purchase date missing. | D9: Left empty — "Days in stock" cannot be calculated. Please fill in.
A10: 6 | B10: VW Touran (08/2019) | C10: Purchase date missing. | D10: Left empty — "Days in stock" cannot be calculated. Please fill in.
A11: 7 | B11: Audi A4 Avant (07/2018) | C11: Purchase date missing. | D11: Left empty — "Days in stock" cannot be calculated. Please fill in.
A12: 8 | B12: Škoda Octavia Combi (03/2018) | C12: Purchase date missing. | D12: Left empty — "Days in stock" cannot be calculated. Please fill in.
A13: 9 | B13: Volkswagen Passat (02/2017) | C13: Purchase date missing. | D13: Left empty — "Days in stock" cannot be calculated. Please fill in.
A14: 13 | B14: Seat Ateca (02/2020) | C14: Old profit (576 €) ≠ sale − costs (566 €) and ≠ sale − costs − VAT column (2,250 €). | D14: "VAT & deductions" set to -10.00 € so profit matches the old sheet. Check which number is right.
A15: 16 | B15: Audi A4 Avant (01/2016) | C15: Old profit (1,768 €) ≠ sale − costs (4,101 €) and ≠ sale − costs − VAT column (1,965 €). | D15: "VAT & deductions" set to 2,333.33 € so profit matches the old sheet. Check which number is right.
... A31: 147 | B31: Audi A6 Avant (11/2019) | C31: Commission / consignment deal: "Costs" is a small fee, not a purchase price. | D31: Marked as Consignment. Commission set to recorded profit + costs = 1,000.00 € so profit stays 950.00 €. Please confirm the real commission.
